[Sun Nov 25 20:22:15 2012] [error] [client 94.40.46.28] File does not exist: /var/www/canvastest/static/base.js, referer: http://canvastest.leszniak.pl/
[Mon Nov 26 06:30:10 2012] [error] [client 79.190.205.211] mod_wsgi (pid=26144): Exception occurred processing WSGI script '/home/projects/canvastest/canvastest/wsgi.py'.
[Mon Nov 26 06:30:10 2012] [error] [client 79.190.205.211] Traceback (most recent call last):
[Mon Nov 26 06:30:10 2012] [error] [client 79.190.205.211]   File "/usr/lib/python2.7/dist-packages/django/core/handlers/wsgi.py", line 219, in __call__
[Mon Nov 26 06:30:10 2012] [error] [client 79.190.205.211]     self.load_middleware()
[Mon Nov 26 06:30:10 2012] [error] [client 79.190.205.211]   File "/usr/lib/python2.7/dist-packages/django/core/handlers/base.py", line 39, in load_middleware
[Mon Nov 26 06:30:10 2012] [error] [client 79.190.205.211]     for middleware_path in settings.MIDDLEWARE_CLASSES:
[Mon Nov 26 06:30:10 2012] [error] [client 79.190.205.211]   File "/usr/lib/python2.7/dist-packages/django/utils/functional.py", line 184, in inner
[Mon Nov 26 06:30:10 2012] [error] [client 79.190.205.211]     self._setup()
[Mon Nov 26 06:30:10 2012] [error] [client 79.190.205.211]   File "/usr/lib/python2.7/dist-packages/django/conf/__init__.py", line 42, in _setup
[Mon Nov 26 06:30:10 2012] [error] [client 79.190.205.211]     self._wrapped = Settings(settings_module)
[Mon Nov 26 06:30:10 2012] [error] [client 79.190.205.211]   File "/usr/lib/python2.7/dist-packages/django/conf/__init__.py", line 95, in __init__
[Mon Nov 26 06:30:10 2012] [error] [client 79.190.205.211]     raise ImportError("Could not import settings '%s' (Is it on sys.path?): %s" % (self.SETTINGS_MODULE, e))
[Mon Nov 26 06:30:10 2012] [error] [client 79.190.205.211] ImportError: Could not import settings 'dcms.settings' (Is it on sys.path?): No module named dcms.settings
[Mon Nov 26 06:40:04 2012] [error] [client 46.248.160.248] mod_wsgi (pid=26144): Exception occurred processing WSGI script '/home/projects/canvastest/canvastest/wsgi.py'.
[Mon Nov 26 06:40:04 2012] [error] [client 46.248.160.248] Traceback (most recent call last):
[Mon Nov 26 06:40:04 2012] [error] [client 46.248.160.248]   File "/usr/lib/python2.7/dist-packages/django/core/handlers/wsgi.py", line 219, in __call__
[Mon Nov 26 06:40:04 2012] [error] [client 46.248.160.248]     self.load_middleware()
[Mon Nov 26 06:40:04 2012] [error] [client 46.248.160.248]   File "/usr/lib/python2.7/dist-packages/django/core/handlers/base.py", line 39, in load_middleware
[Mon Nov 26 06:40:04 2012] [error] [client 46.248.160.248]     for middleware_path in settings.MIDDLEWARE_CLASSES:
[Mon Nov 26 06:40:04 2012] [error] [client 46.248.160.248]   File "/usr/lib/python2.7/dist-packages/django/utils/functional.py", line 184, in inner
[Mon Nov 26 06:40:04 2012] [error] [client 46.248.160.248]     self._setup()
[Mon Nov 26 06:40:04 2012] [error] [client 46.248.160.248]   File "/usr/lib/python2.7/dist-packages/django/conf/__init__.py", line 42, in _setup
[Mon Nov 26 06:40:04 2012] [error] [client 46.248.160.248]     self._wrapped = Settings(settings_module)
[Mon Nov 26 06:40:04 2012] [error] [client 46.248.160.248]   File "/usr/lib/python2.7/dist-packages/django/conf/__init__.py", line 95, in __init__
[Mon Nov 26 06:40:04 2012] [error] [client 46.248.160.248]     raise ImportError("Could not import settings '%s' (Is it on sys.path?): %s" % (self.SETTINGS_MODULE, e))
[Mon Nov 26 06:40:04 2012] [error] [client 46.248.160.248] ImportError: Could not import settings 'dcms.settings' (Is it on sys.path?): No module named dcms.settings
[Mon Nov 26 14:35:50 2012] [error] [client 83.12.83.178] File does not exist: /var/www/canvastest/scripts/testPixels.js, referer: http://canvastest.leszniak.pl/
[Mon Nov 26 07:35:50 2012] [error] [client 83.12.83.178] File does not exist: /var/www/canvastest/scripts/testPixels.js, referer: http://canvastest.leszniak.pl/
[Tue Nov 27 15:26:07 2012] [error] [client 94.40.46.28] mod_wsgi (pid=7207): Exception occurred processing WSGI script '/home/projects/canvastest/canvastest/wsgi.py'., referer: http://canvastest.leszniak.pl/testy
[Tue Nov 27 15:26:07 2012] [error] [client 94.40.46.28] Traceback (most recent call last):, referer: http://canvastest.leszniak.pl/testy
[Tue Nov 27 15:26:07 2012] [error] [client 94.40.46.28]   File "/usr/lib/python2.7/dist-packages/django/core/handlers/wsgi.py", line 219, in __call__, referer: http://canvastest.leszniak.pl/testy
[Tue Nov 27 15:26:07 2012] [error] [client 94.40.46.28]     self.load_middleware(), referer: http://canvastest.leszniak.pl/testy
[Tue Nov 27 15:26:07 2012] [error] [client 94.40.46.28]   File "/usr/lib/python2.7/dist-packages/django/core/handlers/base.py", line 39, in load_middleware, referer: http://canvastest.leszniak.pl/testy
[Tue Nov 27 15:26:07 2012] [error] [client 94.40.46.28]     for middleware_path in settings.MIDDLEWARE_CLASSES:, referer: http://canvastest.leszniak.pl/testy
[Tue Nov 27 15:26:07 2012] [error] [client 94.40.46.28]   File "/usr/lib/python2.7/dist-packages/django/utils/functional.py", line 184, in inner, referer: http://canvastest.leszniak.pl/testy
[Tue Nov 27 15:26:07 2012] [error] [client 94.40.46.28]     self._setup(), referer: http://canvastest.leszniak.pl/testy
[Tue Nov 27 15:26:07 2012] [error] [client 94.40.46.28]   File "/usr/lib/python2.7/dist-packages/django/conf/__init__.py", line 42, in _setup, referer: http://canvastest.leszniak.pl/testy
[Tue Nov 27 15:26:07 2012] [error] [client 94.40.46.28]     self._wrapped = Settings(settings_module), referer: http://canvastest.leszniak.pl/testy
[Tue Nov 27 15:26:07 2012] [error] [client 94.40.46.28]   File "/usr/lib/python2.7/dist-packages/django/conf/__init__.py", line 95, in __init__, referer: http://canvastest.leszniak.pl/testy
[Tue Nov 27 15:26:07 2012] [error] [client 94.40.46.28]     raise ImportError("Could not import settings '%s' (Is it on sys.path?): %s" % (self.SETTINGS_MODULE, e)), referer: http://canvastest.leszniak.pl/testy
[Tue Nov 27 15:26:07 2012] [error] [client 94.40.46.28] ImportError: Could not import settings 'dcms.settings' (Is it on sys.path?): No module named dcms.settings, referer: http://canvastest.leszniak.pl/testy
[Tue Nov 27 15:32:08 2012] [error] [client 94.40.46.28] mod_wsgi (pid=7201): Exception occurred processing WSGI script '/home/projects/canvastest/canvastest/wsgi.py'.
[Tue Nov 27 15:32:08 2012] [error] [client 94.40.46.28] Traceback (most recent call last):
[Tue Nov 27 15:32:08 2012] [error] [client 94.40.46.28]   File "/usr/lib/python2.7/dist-packages/django/core/handlers/wsgi.py", line 219, in __call__
[Tue Nov 27 15:32:08 2012] [error] [client 94.40.46.28]     self.load_middleware()
[Tue Nov 27 15:32:08 2012] [error] [client 94.40.46.28]   File "/usr/lib/python2.7/dist-packages/django/core/handlers/base.py", line 39, in load_middleware
[Tue Nov 27 15:32:08 2012] [error] [client 94.40.46.28]     for middleware_path in settings.MIDDLEWARE_CLASSES:
[Tue Nov 27 15:32:08 2012] [error] [client 94.40.46.28]   File "/usr/lib/python2.7/dist-packages/django/utils/functional.py", line 184, in inner
[Tue Nov 27 15:32:08 2012] [error] [client 94.40.46.28]     self._setup()
[Tue Nov 27 15:32:08 2012] [error] [client 94.40.46.28]   File "/usr/lib/python2.7/dist-packages/django/conf/__init__.py", line 42, in _setup
[Tue Nov 27 15:32:08 2012] [error] [client 94.40.46.28]     self._wrapped = Settings(settings_module)
[Tue Nov 27 15:32:08 2012] [error] [client 94.40.46.28]   File "/usr/lib/python2.7/dist-packages/django/conf/__init__.py", line 95, in __init__
[Tue Nov 27 15:32:08 2012] [error] [client 94.40.46.28]     raise ImportError("Could not import settings '%s' (Is it on sys.path?): %s" % (self.SETTINGS_MODULE, e))
[Tue Nov 27 15:32:08 2012] [error] [client 94.40.46.28] ImportError: Could not import settings 'dcms.settings' (Is it on sys.path?): No module named dcms.settings
[Tue Nov 27 15:36:40 2012] [error] [client 94.40.46.28] mod_wsgi (pid=7207): Exception occurred processing WSGI script '/home/projects/canvastest/canvastest/wsgi.py'.
[Tue Nov 27 15:36:40 2012] [error] [client 94.40.46.28] Traceback (most recent call last):
[Tue Nov 27 15:36:40 2012] [error] [client 94.40.46.28]   File "/usr/lib/python2.7/dist-packages/django/core/handlers/wsgi.py", line 219, in __call__
[Tue Nov 27 15:36:40 2012] [error] [client 94.40.46.28]     self.load_middleware()
[Tue Nov 27 15:36:40 2012] [error] [client 94.40.46.28]   File "/usr/lib/python2.7/dist-packages/django/core/handlers/base.py", line 39, in load_middleware
[Tue Nov 27 15:36:40 2012] [error] [client 94.40.46.28]     for middleware_path in settings.MIDDLEWARE_CLASSES:
[Tue Nov 27 15:36:40 2012] [error] [client 94.40.46.28]   File "/usr/lib/python2.7/dist-packages/django/utils/functional.py", line 184, in inner
[Tue Nov 27 15:36:40 2012] [error] [client 94.40.46.28]     self._setup()
[Tue Nov 27 15:36:40 2012] [error] [client 94.40.46.28]   File "/usr/lib/python2.7/dist-packages/django/conf/__init__.py", line 42, in _setup
[Tue Nov 27 15:36:40 2012] [error] [client 94.40.46.28]     self._wrapped = Settings(settings_module)
[Tue Nov 27 15:36:40 2012] [error] [client 94.40.46.28]   File "/usr/lib/python2.7/dist-packages/django/conf/__init__.py", line 95, in __init__
[Tue Nov 27 15:36:40 2012] [error] [client 94.40.46.28]     raise ImportError("Could not import settings '%s' (Is it on sys.path?): %s" % (self.SETTINGS_MODULE, e))
[Tue Nov 27 15:36:40 2012] [error] [client 94.40.46.28] ImportError: Could not import settings 'dcms.settings' (Is it on sys.path?): No module named dcms.settings
[Wed Nov 28 02:27:21 2012] [error] [client 46.248.160.248] File does not exist: /var/www/canvastest/static/jquery-1.8.3.js, referer: http://canvastest.leszniak.pl/testy
[Thu Nov 29 06:23:44 2012] [error] [client 46.248.160.248] mod_wsgi (pid=28415): Exception occurred processing WSGI script '/home/projects/canvastest/canvastest/wsgi.py'.
[Thu Nov 29 06:23:44 2012] [error] [client 46.248.160.248] IOError: failed to write data
[Thu Nov 29 06:23:46 2012] [error] [client 46.248.160.248] mod_wsgi (pid=28411): Exception occurred processing WSGI script '/home/projects/canvastest/canvastest/wsgi.py'.
[Thu Nov 29 06:23:46 2012] [error] [client 46.248.160.248] IOError: failed to write data
[Thu Nov 29 06:54:15 2012] [error] [client 46.248.160.248] mod_wsgi (pid=28195): Exception occurred processing WSGI script '/home/projects/canvastest/canvastest/wsgi.py'.
[Thu Nov 29 06:54:15 2012] [error] [client 46.248.160.248] Traceback (most recent call last):
[Thu Nov 29 06:54:15 2012] [error] [client 46.248.160.248]   File "/usr/lib/python2.7/dist-packages/django/core/handlers/wsgi.py", line 241, in __call__
[Thu Nov 29 06:54:15 2012] [error] [client 46.248.160.248]     response = self.get_response(request)
[Thu Nov 29 06:54:15 2012] [error] [client 46.248.160.248]   File "/usr/lib/python2.7/dist-packages/django/core/handlers/base.py", line 179, in get_response
[Thu Nov 29 06:54:15 2012] [error] [client 46.248.160.248]     response = self.handle_uncaught_exception(request, resolver, sys.exc_info())
[Thu Nov 29 06:54:15 2012] [error] [client 46.248.160.248]   File "/usr/lib/python2.7/dist-packages/django/core/handlers/base.py", line 221, in handle_uncaught_exception
[Thu Nov 29 06:54:15 2012] [error] [client 46.248.160.248]     return debug.technical_500_response(request, *exc_info)
[Thu Nov 29 06:54:15 2012] [error] [client 46.248.160.248]   File "/usr/lib/python2.7/dist-packages/django/views/debug.py", line 66, in technical_500_response
[Thu Nov 29 06:54:15 2012] [error] [client 46.248.160.248]     html = reporter.get_traceback_html()
[Thu Nov 29 06:54:15 2012] [error] [client 46.248.160.248]   File "/usr/lib/python2.7/dist-packages/django/views/debug.py", line 286, in get_traceback_html
[Thu Nov 29 06:54:15 2012] [error] [client 46.248.160.248]     c = Context(self.get_traceback_data())
[Thu Nov 29 06:54:15 2012] [error] [client 46.248.160.248]   File "/usr/lib/python2.7/dist-packages/django/views/debug.py", line 244, in get_traceback_data
[Thu Nov 29 06:54:15 2012] [error] [client 46.248.160.248]     frames = self.get_traceback_frames()
[Thu Nov 29 06:54:15 2012] [error] [client 46.248.160.248]   File "/usr/lib/python2.7/dist-packages/django/views/debug.py", line 390, in get_traceback_frames
[Thu Nov 29 06:54:15 2012] [error] [client 46.248.160.248]     pre_context_lineno, pre_context, context_line, post_context = self._get_lines_from_file(filename, lineno, 7, loader, module_name)
[Thu Nov 29 06:54:15 2012] [error] [client 46.248.160.248]   File "/usr/lib/python2.7/dist-packages/django/views/debug.py", line 371, in _get_lines_from_file
[Thu Nov 29 06:54:15 2012] [error] [client 46.248.160.248]     context_line = source[lineno].strip('\\n')
[Thu Nov 29 06:54:15 2012] [error] [client 46.248.160.248] IndexError: list index out of range
[Thu Nov 29 06:54:18 2012] [error] [client 46.248.160.248] mod_wsgi (pid=28623): Exception occurred processing WSGI script '/home/projects/canvastest/canvastest/wsgi.py'.
[Thu Nov 29 06:54:18 2012] [error] [client 46.248.160.248] Traceback (most recent call last):
[Thu Nov 29 06:54:18 2012] [error] [client 46.248.160.248]   File "/usr/lib/python2.7/dist-packages/django/core/handlers/wsgi.py", line 241, in __call__
[Thu Nov 29 06:54:18 2012] [error] [client 46.248.160.248]     response = self.get_response(request)
[Thu Nov 29 06:54:18 2012] [error] [client 46.248.160.248]   File "/usr/lib/python2.7/dist-packages/django/core/handlers/base.py", line 179, in get_response
[Thu Nov 29 06:54:18 2012] [error] [client 46.248.160.248]     response = self.handle_uncaught_exception(request, resolver, sys.exc_info())
[Thu Nov 29 06:54:18 2012] [error] [client 46.248.160.248]   File "/usr/lib/python2.7/dist-packages/django/core/handlers/base.py", line 221, in handle_uncaught_exception
[Thu Nov 29 06:54:18 2012] [error] [client 46.248.160.248]     return debug.technical_500_response(request, *exc_info)
[Thu Nov 29 06:54:18 2012] [error] [client 46.248.160.248]   File "/usr/lib/python2.7/dist-packages/django/views/debug.py", line 66, in technical_500_response
[Thu Nov 29 06:54:18 2012] [error] [client 46.248.160.248]     html = reporter.get_traceback_html()
[Thu Nov 29 06:54:18 2012] [error] [client 46.248.160.248]   File "/usr/lib/python2.7/dist-packages/django/views/debug.py", line 286, in get_traceback_html
[Thu Nov 29 06:54:18 2012] [error] [client 46.248.160.248]     c = Context(self.get_traceback_data())
[Thu Nov 29 06:54:18 2012] [error] [client 46.248.160.248]   File "/usr/lib/python2.7/dist-packages/django/views/debug.py", line 244, in get_traceback_data
[Thu Nov 29 06:54:18 2012] [error] [client 46.248.160.248]     frames = self.get_traceback_frames()
[Thu Nov 29 06:54:18 2012] [error] [client 46.248.160.248]   File "/usr/lib/python2.7/dist-packages/django/views/debug.py", line 390, in get_traceback_frames
[Thu Nov 29 06:54:18 2012] [error] [client 46.248.160.248]     pre_context_lineno, pre_context, context_line, post_context = self._get_lines_from_file(filename, lineno, 7, loader, module_name)
[Thu Nov 29 06:54:18 2012] [error] [client 46.248.160.248]   File "/usr/lib/python2.7/dist-packages/django/views/debug.py", line 371, in _get_lines_from_file
[Thu Nov 29 06:54:18 2012] [error] [client 46.248.160.248]     context_line = source[lineno].strip('\\n')
[Thu Nov 29 06:54:18 2012] [error] [client 46.248.160.248] IndexError: list index out of range
[Thu Nov 29 06:54:23 2012] [error] [client 46.248.160.248] mod_wsgi (pid=5248): Exception occurred processing WSGI script '/home/projects/canvastest/canvastest/wsgi.py'.
[Thu Nov 29 06:54:23 2012] [error] [client 46.248.160.248] Traceback (most recent call last):
[Thu Nov 29 06:54:23 2012] [error] [client 46.248.160.248]   File "/usr/lib/python2.7/dist-packages/django/core/handlers/wsgi.py", line 241, in __call__
[Thu Nov 29 06:54:23 2012] [error] [client 46.248.160.248]     response = self.get_response(request)
[Thu Nov 29 06:54:23 2012] [error] [client 46.248.160.248]   File "/usr/lib/python2.7/dist-packages/django/core/handlers/base.py", line 179, in get_response
[Thu Nov 29 06:54:23 2012] [error] [client 46.248.160.248]     response = self.handle_uncaught_exception(request, resolver, sys.exc_info())
[Thu Nov 29 06:54:23 2012] [error] [client 46.248.160.248]   File "/usr/lib/python2.7/dist-packages/django/core/handlers/base.py", line 221, in handle_uncaught_exception
[Thu Nov 29 06:54:23 2012] [error] [client 46.248.160.248]     return debug.technical_500_response(request, *exc_info)
[Thu Nov 29 06:54:23 2012] [error] [client 46.248.160.248]   File "/usr/lib/python2.7/dist-packages/django/views/debug.py", line 66, in technical_500_response
[Thu Nov 29 06:54:23 2012] [error] [client 46.248.160.248]     html = reporter.get_traceback_html()
[Thu Nov 29 06:54:23 2012] [error] [client 46.248.160.248]   File "/usr/lib/python2.7/dist-packages/django/views/debug.py", line 286, in get_traceback_html
[Thu Nov 29 06:54:23 2012] [error] [client 46.248.160.248]     c = Context(self.get_traceback_data())
[Thu Nov 29 06:54:23 2012] [error] [client 46.248.160.248]   File "/usr/lib/python2.7/dist-packages/django/views/debug.py", line 244, in get_traceback_data
[Thu Nov 29 06:54:23 2012] [error] [client 46.248.160.248]     frames = self.get_traceback_frames()
[Thu Nov 29 06:54:23 2012] [error] [client 46.248.160.248]   File "/usr/lib/python2.7/dist-packages/django/views/debug.py", line 390, in get_traceback_frames
[Thu Nov 29 06:54:23 2012] [error] [client 46.248.160.248]     pre_context_lineno, pre_context, context_line, post_context = self._get_lines_from_file(filename, lineno, 7, loader, module_name)
[Thu Nov 29 06:54:23 2012] [error] [client 46.248.160.248]   File "/usr/lib/python2.7/dist-packages/django/views/debug.py", line 371, in _get_lines_from_file
[Thu Nov 29 06:54:23 2012] [error] [client 46.248.160.248]     context_line = source[lineno].strip('\\n')
[Thu Nov 29 06:54:23 2012] [error] [client 46.248.160.248] IndexError: list index out of range
[Thu Nov 29 06:56:44 2012] [error] [client 46.248.160.248] mod_wsgi (pid=28413): Exception occurred processing WSGI script '/home/projects/canvastest/canvastest/wsgi.py'.
[Thu Nov 29 06:56:44 2012] [error] [client 46.248.160.248] Traceback (most recent call last):
[Thu Nov 29 06:56:44 2012] [error] [client 46.248.160.248]   File "/usr/lib/python2.7/dist-packages/django/core/handlers/wsgi.py", line 241, in __call__
[Thu Nov 29 06:56:44 2012] [error] [client 46.248.160.248]     response = self.get_response(request)
[Thu Nov 29 06:56:44 2012] [error] [client 46.248.160.248]   File "/usr/lib/python2.7/dist-packages/django/core/handlers/base.py", line 179, in get_response
[Thu Nov 29 06:56:44 2012] [error] [client 46.248.160.248]     response = self.handle_uncaught_exception(request, resolver, sys.exc_info())
[Thu Nov 29 06:56:44 2012] [error] [client 46.248.160.248]   File "/usr/lib/python2.7/dist-packages/django/core/handlers/base.py", line 221, in handle_uncaught_exception
[Thu Nov 29 06:56:44 2012] [error] [client 46.248.160.248]     return debug.technical_500_response(request, *exc_info)
[Thu Nov 29 06:56:44 2012] [error] [client 46.248.160.248]   File "/usr/lib/python2.7/dist-packages/django/views/debug.py", line 66, in technical_500_response
[Thu Nov 29 06:56:44 2012] [error] [client 46.248.160.248]     html = reporter.get_traceback_html()
[Thu Nov 29 06:56:44 2012] [error] [client 46.248.160.248]   File "/usr/lib/python2.7/dist-packages/django/views/debug.py", line 286, in get_traceback_html
[Thu Nov 29 06:56:44 2012] [error] [client 46.248.160.248]     c = Context(self.get_traceback_data())
[Thu Nov 29 06:56:44 2012] [error] [client 46.248.160.248]   File "/usr/lib/python2.7/dist-packages/django/views/debug.py", line 244, in get_traceback_data
[Thu Nov 29 06:56:44 2012] [error] [client 46.248.160.248]     frames = self.get_traceback_frames()
[Thu Nov 29 06:56:44 2012] [error] [client 46.248.160.248]   File "/usr/lib/python2.7/dist-packages/django/views/debug.py", line 390, in get_traceback_frames
[Thu Nov 29 06:56:44 2012] [error] [client 46.248.160.248]     pre_context_lineno, pre_context, context_line, post_context = self._get_lines_from_file(filename, lineno, 7, loader, module_name)
[Thu Nov 29 06:56:44 2012] [error] [client 46.248.160.248]   File "/usr/lib/python2.7/dist-packages/django/views/debug.py", line 371, in _get_lines_from_file
[Thu Nov 29 06:56:44 2012] [error] [client 46.248.160.248]     context_line = source[lineno].strip('\\n')
[Thu Nov 29 06:56:44 2012] [error] [client 46.248.160.248] IndexError: list index out of range
[Thu Nov 29 06:57:09 2012] [error] [client 46.248.160.248] mod_wsgi (pid=28003): Exception occurred processing WSGI script '/home/projects/canvastest/canvastest/wsgi.py'.
[Thu Nov 29 06:57:09 2012] [error] [client 46.248.160.248] Traceback (most recent call last):
[Thu Nov 29 06:57:09 2012] [error] [client 46.248.160.248]   File "/usr/lib/python2.7/dist-packages/django/core/handlers/wsgi.py", line 241, in __call__
[Thu Nov 29 06:57:09 2012] [error] [client 46.248.160.248]     response = self.get_response(request)
[Thu Nov 29 06:57:09 2012] [error] [client 46.248.160.248]   File "/usr/lib/python2.7/dist-packages/django/core/handlers/base.py", line 179, in get_response
[Thu Nov 29 06:57:09 2012] [error] [client 46.248.160.248]     response = self.handle_uncaught_exception(request, resolver, sys.exc_info())
[Thu Nov 29 06:57:09 2012] [error] [client 46.248.160.248]   File "/usr/lib/python2.7/dist-packages/django/core/handlers/base.py", line 221, in handle_uncaught_exception
[Thu Nov 29 06:57:09 2012] [error] [client 46.248.160.248]     return debug.technical_500_response(request, *exc_info)
[Thu Nov 29 06:57:09 2012] [error] [client 46.248.160.248]   File "/usr/lib/python2.7/dist-packages/django/views/debug.py", line 66, in technical_500_response
[Thu Nov 29 06:57:09 2012] [error] [client 46.248.160.248]     html = reporter.get_traceback_html()
[Thu Nov 29 06:57:09 2012] [error] [client 46.248.160.248]   File "/usr/lib/python2.7/dist-packages/django/views/debug.py", line 286, in get_traceback_html
[Thu Nov 29 06:57:09 2012] [error] [client 46.248.160.248]     c = Context(self.get_traceback_data())
[Thu Nov 29 06:57:09 2012] [error] [client 46.248.160.248]   File "/usr/lib/python2.7/dist-packages/django/views/debug.py", line 244, in get_traceback_data
[Thu Nov 29 06:57:09 2012] [error] [client 46.248.160.248]     frames = self.get_traceback_frames()
[Thu Nov 29 06:57:09 2012] [error] [client 46.248.160.248]   File "/usr/lib/python2.7/dist-packages/django/views/debug.py", line 390, in get_traceback_frames
[Thu Nov 29 06:57:09 2012] [error] [client 46.248.160.248]     pre_context_lineno, pre_context, context_line, post_context = self._get_lines_from_file(filename, lineno, 7, loader, module_name)
[Thu Nov 29 06:57:09 2012] [error] [client 46.248.160.248]   File "/usr/lib/python2.7/dist-packages/django/views/debug.py", line 371, in _get_lines_from_file
[Thu Nov 29 06:57:09 2012] [error] [client 46.248.160.248]     context_line = source[lineno].strip('\\n')
[Thu Nov 29 06:57:09 2012] [error] [client 46.248.160.248] IndexError: list index out of range
[Thu Nov 29 06:57:15 2012] [error] [client 46.248.160.248] mod_wsgi (pid=28197): Exception occurred processing WSGI script '/home/projects/canvastest/canvastest/wsgi.py'.
[Thu Nov 29 06:57:15 2012] [error] [client 46.248.160.248] Traceback (most recent call last):
[Thu Nov 29 06:57:15 2012] [error] [client 46.248.160.248]   File "/usr/lib/python2.7/dist-packages/django/core/handlers/wsgi.py", line 241, in __call__
[Thu Nov 29 06:57:15 2012] [error] [client 46.248.160.248]     response = self.get_response(request)
[Thu Nov 29 06:57:15 2012] [error] [client 46.248.160.248]   File "/usr/lib/python2.7/dist-packages/django/core/handlers/base.py", line 179, in get_response
[Thu Nov 29 06:57:15 2012] [error] [client 46.248.160.248]     response = self.handle_uncaught_exception(request, resolver, sys.exc_info())
[Thu Nov 29 06:57:15 2012] [error] [client 46.248.160.248]   File "/usr/lib/python2.7/dist-packages/django/core/handlers/base.py", line 221, in handle_uncaught_exception
[Thu Nov 29 06:57:15 2012] [error] [client 46.248.160.248]     return debug.technical_500_response(request, *exc_info)
[Thu Nov 29 06:57:15 2012] [error] [client 46.248.160.248]   File "/usr/lib/python2.7/dist-packages/django/views/debug.py", line 66, in technical_500_response
[Thu Nov 29 06:57:15 2012] [error] [client 46.248.160.248]     html = reporter.get_traceback_html()
[Thu Nov 29 06:57:15 2012] [error] [client 46.248.160.248]   File "/usr/lib/python2.7/dist-packages/django/views/debug.py", line 286, in get_traceback_html
[Thu Nov 29 06:57:15 2012] [error] [client 46.248.160.248]     c = Context(self.get_traceback_data())
[Thu Nov 29 06:57:15 2012] [error] [client 46.248.160.248]   File "/usr/lib/python2.7/dist-packages/django/views/debug.py", line 244, in get_traceback_data
[Thu Nov 29 06:57:15 2012] [error] [client 46.248.160.248]     frames = self.get_traceback_frames()
[Thu Nov 29 06:57:15 2012] [error] [client 46.248.160.248]   File "/usr/lib/python2.7/dist-packages/django/views/debug.py", line 390, in get_traceback_frames
[Thu Nov 29 06:57:15 2012] [error] [client 46.248.160.248]     pre_context_lineno, pre_context, context_line, post_context = self._get_lines_from_file(filename, lineno, 7, loader, module_name)
[Thu Nov 29 06:57:15 2012] [error] [client 46.248.160.248]   File "/usr/lib/python2.7/dist-packages/django/views/debug.py", line 371, in _get_lines_from_file
[Thu Nov 29 06:57:15 2012] [error] [client 46.248.160.248]     context_line = source[lineno].strip('\\n')
[Thu Nov 29 06:57:15 2012] [error] [client 46.248.160.248] IndexError: list index out of range
[Thu Nov 29 06:58:21 2012] [error] [client 46.248.160.248] mod_wsgi (pid=5248): Exception occurred processing WSGI script '/home/projects/canvastest/canvastest/wsgi.py'.
[Thu Nov 29 06:58:21 2012] [error] [client 46.248.160.248] Traceback (most recent call last):
[Thu Nov 29 06:58:21 2012] [error] [client 46.248.160.248]   File "/usr/lib/python2.7/dist-packages/django/core/handlers/wsgi.py", line 241, in __call__
[Thu Nov 29 06:58:21 2012] [error] [client 46.248.160.248]     response = self.get_response(request)
[Thu Nov 29 06:58:21 2012] [error] [client 46.248.160.248]   File "/usr/lib/python2.7/dist-packages/django/core/handlers/base.py", line 179, in get_response
[Thu Nov 29 06:58:21 2012] [error] [client 46.248.160.248]     response = self.handle_uncaught_exception(request, resolver, sys.exc_info())
[Thu Nov 29 06:58:21 2012] [error] [client 46.248.160.248]   File "/usr/lib/python2.7/dist-packages/django/core/handlers/base.py", line 221, in handle_uncaught_exception
[Thu Nov 29 06:58:21 2012] [error] [client 46.248.160.248]     return debug.technical_500_response(request, *exc_info)
[Thu Nov 29 06:58:21 2012] [error] [client 46.248.160.248]   File "/usr/lib/python2.7/dist-packages/django/views/debug.py", line 66, in technical_500_response
[Thu Nov 29 06:58:21 2012] [error] [client 46.248.160.248]     html = reporter.get_traceback_html()
[Thu Nov 29 06:58:21 2012] [error] [client 46.248.160.248]   File "/usr/lib/python2.7/dist-packages/django/views/debug.py", line 286, in get_traceback_html
[Thu Nov 29 06:58:21 2012] [error] [client 46.248.160.248]     c = Context(self.get_traceback_data())
[Thu Nov 29 06:58:21 2012] [error] [client 46.248.160.248]   File "/usr/lib/python2.7/dist-packages/django/views/debug.py", line 244, in get_traceback_data
[Thu Nov 29 06:58:21 2012] [error] [client 46.248.160.248]     frames = self.get_traceback_frames()
[Thu Nov 29 06:58:21 2012] [error] [client 46.248.160.248]   File "/usr/lib/python2.7/dist-packages/django/views/debug.py", line 390, in get_traceback_frames
[Thu Nov 29 06:58:21 2012] [error] [client 46.248.160.248]     pre_context_lineno, pre_context, context_line, post_context = self._get_lines_from_file(filename, lineno, 7, loader, module_name)
[Thu Nov 29 06:58:21 2012] [error] [client 46.248.160.248]   File "/usr/lib/python2.7/dist-packages/django/views/debug.py", line 371, in _get_lines_from_file
[Thu Nov 29 06:58:21 2012] [error] [client 46.248.160.248]     context_line = source[lineno].strip('\\n')
[Thu Nov 29 06:58:21 2012] [error] [client 46.248.160.248] IndexError: list index out of range
[Thu Nov 29 12:06:07 2012] [error] [client 94.40.46.28] mod_wsgi (pid=3527): Exception occurred processing WSGI script '/home/projects/canvastest/canvastest/wsgi.py'., referer: http://canvastest.leszniak.pl/wyszukaj
[Thu Nov 29 12:06:07 2012] [error] [client 94.40.46.28] IOError: failed to write data, referer: http://canvastest.leszniak.pl/wyszukaj
[Thu Nov 29 12:06:12 2012] [error] [client 94.40.46.28] mod_wsgi (pid=32592): Exception occurred processing WSGI script '/home/projects/canvastest/canvastest/wsgi.py'., referer: http://canvastest.leszniak.pl/wyszukaj
[Thu Nov 29 12:06:12 2012] [error] [client 94.40.46.28] IOError: failed to write data, referer: http://canvastest.leszniak.pl/wyszukaj
[Thu Nov 29 12:43:07 2012] [error] [client 94.40.46.28] mod_wsgi (pid=5650): Exception occurred processing WSGI script '/home/projects/canvastest/canvastest/wsgi.py'.
[Thu Nov 29 12:43:07 2012] [error] [client 94.40.46.28] IOError: failed to write data
[Thu Nov 29 13:29:28 2012] [error] [client 95.108.82.99] mod_wsgi (pid=7207): Exception occurred processing WSGI script '/home/projects/canvastest/canvastest/wsgi.py'., referer: http://canvastest.leszniak.pl/
[Thu Nov 29 13:29:28 2012] [error] [client 95.108.82.99] IOError: failed to write data, referer: http://canvastest.leszniak.pl/
[Thu Nov 29 20:29:28 2012] [error] [client 95.108.82.99] mod_wsgi (pid=7209): Exception occurred processing WSGI script '/home/projects/canvastest/canvastest/wsgi.py'., referer: http://canvastest.leszniak.pl/
[Thu Nov 29 20:29:28 2012] [error] [client 95.108.82.99] IOError: failed to write data, referer: http://canvastest.leszniak.pl/
[Thu Nov 29 13:32:54 2012] [error] [client 95.108.82.99] mod_wsgi (pid=7207): Exception occurred processing WSGI script '/home/projects/canvastest/canvastest/wsgi.py'., referer: http://canvastest.leszniak.pl/
[Thu Nov 29 13:32:54 2012] [error] [client 95.108.82.99] IOError: failed to write data, referer: http://canvastest.leszniak.pl/
[Thu Nov 29 13:32:55 2012] [error] [client 95.108.82.99] mod_wsgi (pid=7209): Exception occurred processing WSGI script '/home/projects/canvastest/canvastest/wsgi.py'., referer: http://canvastest.leszniak.pl/
[Thu Nov 29 13:32:55 2012] [error] [client 95.108.82.99] IOError: failed to write data, referer: http://canvastest.leszniak.pl/
[Thu Nov 29 13:34:39 2012] [error] [client 95.108.82.99] mod_wsgi (pid=7689): Exception occurred processing WSGI script '/home/projects/canvastest/canvastest/wsgi.py'., referer: http://canvastest.leszniak.pl/
[Thu Nov 29 13:34:39 2012] [error] [client 95.108.82.99] IOError: failed to write data, referer: http://canvastest.leszniak.pl/
[Thu Nov 29 13:36:35 2012] [error] [client 94.40.46.28] mod_wsgi (pid=7691): Exception occurred processing WSGI script '/home/projects/canvastest/canvastest/wsgi.py'., referer: http://canvastest.leszniak.pl/
[Thu Nov 29 13:36:35 2012] [error] [client 94.40.46.28] IOError: failed to write data, referer: http://canvastest.leszniak.pl/
[Thu Nov 29 13:36:36 2012] [error] [client 94.40.46.28] mod_wsgi (pid=7697): Exception occurred processing WSGI script '/home/projects/canvastest/canvastest/wsgi.py'., referer: http://canvastest.leszniak.pl/
[Thu Nov 29 13:36:36 2012] [error] [client 94.40.46.28] IOError: failed to write data, referer: http://canvastest.leszniak.pl/
[Thu Nov 29 13:38:15 2012] [error] [client 94.40.46.28] mod_wsgi (pid=7699): Exception occurred processing WSGI script '/home/projects/canvastest/canvastest/wsgi.py'., referer: http://canvastest.leszniak.pl/
[Thu Nov 29 13:38:15 2012] [error] [client 94.40.46.28] IOError: failed to write data, referer: http://canvastest.leszniak.pl/
[Thu Nov 29 13:48:39 2012] [error] [client 94.40.46.28] mod_wsgi (pid=7698): Exception occurred processing WSGI script '/home/projects/canvastest/canvastest/wsgi.py'.
[Thu Nov 29 13:48:39 2012] [error] [client 94.40.46.28] MemoryError
[Thu Nov 29 13:48:39 2012] [error] [client 94.40.46.28] unable to init Zlib: deflateInit2 returned -4: URL /charts/browser_pie.png
[Thu Nov 29 13:48:40 2012] [error] [client 94.40.46.28] mod_wsgi (pid=7697): Exception occurred processing WSGI script '/home/projects/canvastest/canvastest/wsgi.py'.
[Thu Nov 29 13:48:40 2012] [error] [client 94.40.46.28] Traceback (most recent call last):
[Thu Nov 29 13:48:40 2012] [error] [client 94.40.46.28]   File "/usr/lib/python2.7/dist-packages/django/core/handlers/wsgi.py", line 241, in __call__
[Thu Nov 29 13:48:40 2012] [error] [client 94.40.46.28]     response = self.get_response(request)
[Thu Nov 29 13:48:40 2012] [error] [client 94.40.46.28]   File "/usr/lib/python2.7/dist-packages/django/core/handlers/base.py", line 179, in get_response
[Thu Nov 29 13:48:40 2012] [error] [client 94.40.46.28]     response = self.handle_uncaught_exception(request, resolver, sys.exc_info())
[Thu Nov 29 13:48:40 2012] [error] [client 94.40.46.28]   File "/usr/lib/python2.7/dist-packages/django/core/handlers/base.py", line 221, in handle_uncaught_exception
[Thu Nov 29 13:48:40 2012] [error] [client 94.40.46.28]     return debug.technical_500_response(request, *exc_info)
[Thu Nov 29 13:48:40 2012] [error] [client 94.40.46.28]   File "/usr/lib/python2.7/dist-packages/django/views/debug.py", line 66, in technical_500_response
[Thu Nov 29 13:48:40 2012] [error] [client 94.40.46.28]     html = reporter.get_traceback_html()
[Thu Nov 29 13:48:40 2012] [error] [client 94.40.46.28]   File "/usr/lib/python2.7/dist-packages/django/views/debug.py", line 287, in get_traceback_html
[Thu Nov 29 13:48:40 2012] [error] [client 94.40.46.28]     return t.render(c)
[Thu Nov 29 13:48:40 2012] [error] [client 94.40.46.28]   File "/usr/lib/python2.7/dist-packages/django/template/base.py", line 140, in render
[Thu Nov 29 13:48:40 2012] [error] [client 94.40.46.28] unable to init Zlib: deflateInit2 returned -4: URL /charts/browser_pie.png
[Thu Nov 29 13:48:41 2012] [error] [client 94.40.46.28] mod_wsgi (pid=7692): Exception occurred processing WSGI script '/home/projects/canvastest/canvastest/wsgi.py'.
[Thu Nov 29 13:48:41 2012] [error] [client 94.40.46.28] Traceback (most recent call last):
[Thu Nov 29 13:48:41 2012] [error] [client 94.40.46.28]   File "/usr/lib/python2.7/dist-packages/django/core/handlers/wsgi.py", line 241, in __call__
[Thu Nov 29 13:48:41 2012] [error] [client 94.40.46.28]     response = self.get_response(request)
[Thu Nov 29 13:48:41 2012] [error] [client 94.40.46.28]   File "/usr/lib/python2.7/dist-packages/django/core/handlers/base.py", line 179, in get_response
[Thu Nov 29 13:48:41 2012] [error] [client 94.40.46.28]     response = self.handle_uncaught_exception(request, resolver, sys.exc_info())
[Thu Nov 29 13:48:41 2012] [error] [client 94.40.46.28]   File "/usr/lib/python2.7/dist-packages/django/core/handlers/base.py", line 221, in handle_uncaught_exception
[Thu Nov 29 13:48:41 2012] [error] [client 94.40.46.28]     return debug.technical_500_response(request, *exc_info)
[Thu Nov 29 13:48:41 2012] [error] [client 94.40.46.28]   File "/usr/lib/python2.7/dist-packages/django/views/debug.py", line 66, in technical_500_response
[Thu Nov 29 13:48:41 2012] [error] [client 94.40.46.28]     html = reporter.get_traceback_html()
[Thu Nov 29 13:48:41 2012] [error] [client 94.40.46.28]   File "/usr/lib/python2.7/dist-packages/django/views/debug.py", line 287, in get_traceback_html
[Thu Nov 29 13:48:41 2012] [error] [client 94.40.46.28]     return t.render(c)
[Thu Nov 29 13:48:41 2012] [error] [client 94.40.46.28]   File "/usr/lib/python2.7/dist-packages/django/template/base.py", line 140, in render
[Thu Nov 29 13:48:41 2012] [error] [client 94.40.46.28]     return self._render(context)
[Thu Nov 29 13:48:41 2012] [error] [client 94.40.46.28]   File "/usr/lib/python2.7/dist-packages/django/template/base.py", line 134, in _render
[Thu Nov 29 13:48:41 2012] [error] [client 94.40.46.28]     return self.nodelist.render(context)
[Thu Nov 29 13:48:41 2012] [error] [client 94.40.46.28]   File "/usr/lib/python2.7/dist-packages/django/template/base.py", line 823, in render
[Thu Nov 29 13:48:41 2012] [error] [client 94.40.46.28]     bit = self.render_node(node, context)
[Thu Nov 29 13:48:41 2012] [error] [client 94.40.46.28]   File "/usr/lib/python2.7/dist-packages/django/template/debug.py", line 74, in render_node
[Thu Nov 29 13:48:41 2012] [error] [client 94.40.46.28]     return node.render(context)
[Thu Nov 29 13:48:41 2012] [error] [client 94.40.46.28]   File "/usr/lib/python2.7/dist-packages/django/template/defaulttags.py", line 281, in render
[Thu Nov 29 13:48:41 2012] [error] [client 94.40.46.28]     return nodelist.render(context)
[Thu Nov 29 13:48:41 2012] [error] [client 94.40.46.28]   File "/usr/lib/python2.7/dist-packages/django/template/base.py", line 823, in render
[Thu Nov 29 13:48:41 2012] [error] [client 94.40.46.28]     bit = self.render_node(node, context)
[Thu Nov 29 13:48:41 2012] [error] [client 94.40.46.28]   File "/usr/lib/python2.7/dist-packages/django/template/debug.py", line 74, in render_node
[Thu Nov 29 13:48:41 2012] [error] [client 94.40.46.28]     return node.render(context)
[Thu Nov 29 13:48:41 2012] [error] [client 94.40.46.28]   File "/usr/lib/python2.7/dist-packages/django/template/defaulttags.py", line 30, in render
[Thu Nov 29 13:48:41 2012] [error] [client 94.40.46.28]     output = self.nodelist.render(context)
[Thu Nov 29 13:48:41 2012] [error] [client 94.40.46.28]   File "/usr/lib/python2.7/dist-packages/django/template/base.py", line 823, in render
[Thu Nov 29 13:48:41 2012] [error] [client 94.40.46.28]     bit = self.render_node(node, context)
[Thu Nov 29 13:48:41 2012] [error] [client 94.40.46.28]   File "/usr/lib/python2.7/dist-packages/django/template/debug.py", line 74, in render_node
[Thu Nov 29 13:48:41 2012] [error] [client 94.40.46.28]     return node.render(context)
[Thu Nov 29 13:48:41 2012] [error] [client 94.40.46.28]   File "/usr/lib/python2.7/dist-packages/django/template/defaulttags.py", line 185, in render
[Thu Nov 29 13:48:41 2012] [error] [client 94.40.46.28]     nodelist.append(node.render(context))
[Thu Nov 29 13:48:41 2012] [error] [client 94.40.46.28]   File "/usr/lib/python2.7/dist-packages/django/template/defaulttags.py", line 281, in render
[Thu Nov 29 13:48:41 2012] [error] [client 94.40.46.28]     return nodelist.render(context)
[Thu Nov 29 13:48:41 2012] [error] [client 94.40.46.28]   File "/usr/lib/python2.7/dist-packages/django/template/base.py", line 827, in render
[Thu Nov 29 13:48:41 2012] [error] [client 94.40.46.28]     return mark_safe(u''.join(bits))
[Thu Nov 29 13:48:41 2012] [error] [client 94.40.46.28] MemoryError
[Thu Nov 29 13:48:41 2012] [error] [client 94.40.46.28] unable to init Zlib: deflateInit2 returned -4: URL /charts/browser_pie.png
[Thu Nov 29 14:25:48 2012] [error] [client 94.40.46.28] mod_wsgi (pid=9232): Exception occurred processing WSGI script '/home/projects/canvastest/canvastest/wsgi.py'., referer: http://canvastest.leszniak.pl/
[Thu Nov 29 14:25:48 2012] [error] [client 94.40.46.28] IOError: failed to write data, referer: http://canvastest.leszniak.pl/
[Thu Nov 29 14:26:06 2012] [error] [client 94.40.46.28] mod_wsgi (pid=9234): Exception occurred processing WSGI script '/home/projects/canvastest/canvastest/wsgi.py'.
[Thu Nov 29 14:26:06 2012] [error] [client 94.40.46.28] IOError: failed to write data
[Thu Nov 29 14:26:07 2012] [error] [client 94.40.46.28] mod_wsgi (pid=9288): Exception occurred processing WSGI script '/home/projects/canvastest/canvastest/wsgi.py'.
[Thu Nov 29 14:26:07 2012] [error] [client 94.40.46.28] IOError: failed to write data
[Thu Nov 29 14:26:07 2012] [error] [client 94.40.46.28] mod_wsgi (pid=9229): Exception occurred processing WSGI script '/home/projects/canvastest/canvastest/wsgi.py'.
[Thu Nov 29 14:26:07 2012] [error] [client 94.40.46.28] IOError: failed to write data
[Thu Nov 29 14:26:30 2012] [error] [client 94.40.46.28] mod_wsgi (pid=9362): Exception occurred processing WSGI script '/home/projects/canvastest/canvastest/wsgi.py'.
[Thu Nov 29 14:26:30 2012] [error] [client 94.40.46.28] IOError: failed to write data
[Thu Nov 29 15:35:48 2012] [error] [client 94.40.46.28] mod_wsgi (pid=9365): Exception occurred processing WSGI script '/home/projects/canvastest/canvastest/wsgi.py'., referer: http://canvastest.leszniak.pl/
[Thu Nov 29 15:35:48 2012] [error] [client 94.40.46.28] Traceback (most recent call last):, referer: http://canvastest.leszniak.pl/
[Thu Nov 29 15:35:48 2012] [error] [client 94.40.46.28]   File "/usr/lib/python2.7/dist-packages/django/core/handlers/wsgi.py", line 241, in __call__, referer: http://canvastest.leszniak.pl/
[Thu Nov 29 15:35:48 2012] [error] [client 94.40.46.28]     response = self.get_response(request), referer: http://canvastest.leszniak.pl/
[Thu Nov 29 15:35:48 2012] [error] [client 94.40.46.28]   File "/usr/lib/python2.7/dist-packages/django/core/handlers/base.py", line 179, in get_response, referer: http://canvastest.leszniak.pl/
[Thu Nov 29 15:35:48 2012] [error] [client 94.40.46.28]     response = self.handle_uncaught_exception(request, resolver, sys.exc_info()), referer: http://canvastest.leszniak.pl/
[Thu Nov 29 15:35:48 2012] [error] [client 94.40.46.28]   File "/usr/lib/python2.7/dist-packages/django/core/handlers/base.py", line 221, in handle_uncaught_exception, referer: http://canvastest.leszniak.pl/
[Thu Nov 29 15:35:48 2012] [error] [client 94.40.46.28]     return debug.technical_500_response(request, *exc_info), referer: http://canvastest.leszniak.pl/
[Thu Nov 29 15:35:48 2012] [error] [client 94.40.46.28]   File "/usr/lib/python2.7/dist-packages/django/views/debug.py", line 66, in technical_500_response, referer: http://canvastest.leszniak.pl/
[Thu Nov 29 15:35:48 2012] [error] [client 94.40.46.28] unable to init Zlib: deflateInit2 returned -4: URL /charts/browser_pie.png, referer: http://canvastest.leszniak.pl/
[Thu Nov 29 15:36:01 2012] [error] [client 94.40.46.28] mod_wsgi (pid=9359): Exception occurred processing WSGI script '/home/projects/canvastest/canvastest/wsgi.py'.
[Thu Nov 29 15:36:01 2012] [error] [client 94.40.46.28] Traceback (most recent call last):
[Thu Nov 29 15:36:01 2012] [error] [client 94.40.46.28]   File "/usr/lib/python2.7/dist-packages/django/core/handlers/wsgi.py", line 241, in __call__
[Thu Nov 29 15:36:01 2012] [error] [client 94.40.46.28]     response = self.get_response(request)
[Thu Nov 29 15:36:01 2012] [error] [client 94.40.46.28]   File "/usr/lib/python2.7/dist-packages/django/core/handlers/base.py", line 179, in get_response
[Thu Nov 29 15:36:01 2012] [error] [client 94.40.46.28]     response = self.handle_uncaught_exception(request, resolver, sys.exc_info())
[Thu Nov 29 15:36:01 2012] [error] [client 94.40.46.28]   File "/usr/lib/python2.7/dist-packages/django/core/handlers/base.py", line 221, in handle_uncaught_exception
[Thu Nov 29 15:36:01 2012] [error] [client 94.40.46.28]     return debug.technical_500_response(request, *exc_info)
[Thu Nov 29 15:36:01 2012] [error] [client 94.40.46.28]   File "/usr/lib/python2.7/dist-packages/django/views/debug.py", line 66, in technical_500_response
[Thu Nov 29 15:36:01 2012] [error] [client 94.40.46.28] unable to init Zlib: deflateInit2 returned -4: URL /charts/browser_pie.png
[Thu Nov 29 15:36:05 2012] [error] [client 94.40.46.28] unable to init Zlib: deflateInit2 returned -4: URL /charts/browsers_pie.png
[Thu Nov 29 15:36:11 2012] [error] [client 94.40.46.28] mod_wsgi (pid=9357): Exception occurred processing WSGI script '/home/projects/canvastest/canvastest/wsgi.py'.
[Thu Nov 29 15:36:11 2012] [error] [client 94.40.46.28] Traceback (most recent call last):
[Thu Nov 29 15:36:11 2012] [error] [client 94.40.46.28]   File "/usr/lib/python2.7/dist-packages/django/core/handlers/wsgi.py", line 241, in __call__
[Thu Nov 29 15:36:11 2012] [error] [client 94.40.46.28]     response = self.get_response(request)
[Thu Nov 29 15:36:11 2012] [error] [client 94.40.46.28]   File "/usr/lib/python2.7/dist-packages/django/core/handlers/base.py", line 179, in get_response
[Thu Nov 29 15:36:11 2012] [error] [client 94.40.46.28]     response = self.handle_uncaught_exception(request, resolver, sys.exc_info())
[Thu Nov 29 15:36:11 2012] [error] [client 94.40.46.28]   File "/usr/lib/python2.7/dist-packages/django/core/handlers/base.py", line 221, in handle_uncaught_exception
[Thu Nov 29 15:36:11 2012] [error] [client 94.40.46.28]     return debug.technical_500_response(request, *exc_info)
[Thu Nov 29 15:36:11 2012] [error] [client 94.40.46.28]   File "/usr/lib/python2.7/dist-packages/django/views/debug.py", line 66, in technical_500_response
[Thu Nov 29 15:36:11 2012] [error] [client 94.40.46.28] unable to init Zlib: deflateInit2 returned -4: URL /charts/browser_pie.png
[Thu Nov 29 15:36:13 2012] [error] [client 94.40.46.28] mod_wsgi (pid=9534): Exception occurred processing WSGI script '/home/projects/canvastest/canvastest/wsgi.py'.
[Thu Nov 29 15:36:13 2012] [error] [client 94.40.46.28] Traceback (most recent call last):
[Thu Nov 29 15:36:13 2012] [error] [client 94.40.46.28]   File "/usr/lib/python2.7/dist-packages/django/core/handlers/wsgi.py", line 241, in __call__
[Thu Nov 29 15:36:13 2012] [error] [client 94.40.46.28]     response = self.get_response(request)
[Thu Nov 29 15:36:13 2012] [error] [client 94.40.46.28]   File "/usr/lib/python2.7/dist-packages/django/core/handlers/base.py", line 179, in get_response
[Thu Nov 29 15:36:13 2012] [error] [client 94.40.46.28]     response = self.handle_uncaught_exception(request, resolver, sys.exc_info())
[Thu Nov 29 15:36:13 2012] [error] [client 94.40.46.28] MemoryError
[Thu Nov 29 15:36:13 2012] [error] [client 94.40.46.28] unable to init Zlib: deflateInit2 returned -4: URL /charts/browser_pie.png
[Thu Nov 29 15:36:14 2012] [error] [client 94.40.46.28] mod_wsgi (pid=9364): Exception occurred processing WSGI script '/home/projects/canvastest/canvastest/wsgi.py'.
[Thu Nov 29 15:36:14 2012] [error] [client 94.40.46.28] Traceback (most recent call last):
[Thu Nov 29 15:36:14 2012] [error] [client 94.40.46.28]   File "/usr/lib/python2.7/dist-packages/django/core/handlers/wsgi.py", line 241, in __call__
[Thu Nov 29 15:36:14 2012] [error] [client 94.40.46.28]     response = self.get_response(request)
[Thu Nov 29 15:36:14 2012] [error] [client 94.40.46.28]   File "/usr/lib/python2.7/dist-packages/django/core/handlers/base.py", line 179, in get_response
[Thu Nov 29 15:36:14 2012] [error] [client 94.40.46.28]     response = self.handle_uncaught_exception(request, resolver, sys.exc_info())
[Thu Nov 29 15:36:14 2012] [error] [client 94.40.46.28]   File "/usr/lib/python2.7/dist-packages/django/core/handlers/base.py", line 221, in handle_uncaught_exception
[Thu Nov 29 15:36:14 2012] [error] [client 94.40.46.28]     return debug.technical_500_response(request, *exc_info)
[Thu Nov 29 15:36:14 2012] [error] [client 94.40.46.28]   File "/usr/lib/python2.7/dist-packages/django/views/debug.py", line 61, in technical_500_response
[Thu Nov 29 15:36:14 2012] [error] [client 94.40.46.28]     reporter = ExceptionReporter(request, exc_type, exc_value, tb)
[Thu Nov 29 15:36:14 2012] [error] [client 94.40.46.28]   File "/usr/lib/python2.7/dist-packages/django/views/debug.py", line 208, in __init__
[Thu Nov 29 15:36:14 2012] [error] [client 94.40.46.28]     self.is_email = is_email
[Thu Nov 29 15:36:14 2012] [error] [client 94.40.46.28] MemoryError
[Thu Nov 29 15:36:14 2012] [error] [client 94.40.46.28] unable to init Zlib: deflateInit2 returned -4: URL /charts/browser_pie.png
[Thu Nov 29 15:36:15 2012] [error] [client 94.40.46.28] mod_wsgi (pid=9363): Exception occurred processing WSGI script '/home/projects/canvastest/canvastest/wsgi.py'.
[Thu Nov 29 15:36:15 2012] [error] [client 94.40.46.28] Traceback (most recent call last):
[Thu Nov 29 15:36:15 2012] [error] [client 94.40.46.28]   File "/usr/lib/python2.7/dist-packages/django/core/handlers/wsgi.py", line 241, in __call__
[Thu Nov 29 15:36:15 2012] [error] [client 94.40.46.28]     response = self.get_response(request)
[Thu Nov 29 15:36:15 2012] [error] [client 94.40.46.28]   File "/usr/lib/python2.7/dist-packages/django/core/handlers/base.py", line 179, in get_response
[Thu Nov 29 15:36:15 2012] [error] [client 94.40.46.28]     response = self.handle_uncaught_exception(request, resolver, sys.exc_info())
[Thu Nov 29 15:36:15 2012] [error] [client 94.40.46.28]   File "/usr/lib/python2.7/dist-packages/django/core/handlers/base.py", line 221, in handle_uncaught_exception
[Thu Nov 29 15:36:15 2012] [error] [client 94.40.46.28]     return debug.technical_500_response(request, *exc_info)
[Thu Nov 29 15:36:15 2012] [error] [client 94.40.46.28]   File "/usr/lib/python2.7/dist-packages/django/views/debug.py", line 66, in technical_500_response
[Thu Nov 29 15:36:15 2012] [error] [client 94.40.46.28] unable to init Zlib: deflateInit2 returned -4: URL /charts/browser_pie.png
[Thu Nov 29 15:36:15 2012] [error] [client 94.40.46.28] mod_wsgi (pid=9362): Exception occurred processing WSGI script '/home/projects/canvastest/canvastest/wsgi.py'.
[Thu Nov 29 15:36:15 2012] [error] [client 94.40.46.28] Traceback (most recent call last):
[Thu Nov 29 15:36:15 2012] [error] [client 94.40.46.28]   File "/usr/lib/python2.7/dist-packages/django/core/handlers/wsgi.py", line 241, in __call__
[Thu Nov 29 15:36:15 2012] [error] [client 94.40.46.28]     response = self.get_response(request)
[Thu Nov 29 15:36:15 2012] [error] [client 94.40.46.28]   File "/usr/lib/python2.7/dist-packages/django/core/handlers/base.py", line 179, in get_response
[Thu Nov 29 15:36:15 2012] [error] [client 94.40.46.28]     response = self.handle_uncaught_exception(request, resolver, sys.exc_info())
[Thu Nov 29 15:36:15 2012] [error] [client 94.40.46.28]   File "/usr/lib/python2.7/dist-packages/django/core/handlers/base.py", line 221, in handle_uncaught_exception
[Thu Nov 29 15:36:15 2012] [error] [client 94.40.46.28]     return debug.technical_500_response(request, *exc_info)
[Thu Nov 29 15:36:15 2012] [error] [client 94.40.46.28]   File "/usr/lib/python2.7/dist-packages/django/views/debug.py", line 66, in technical_500_response
[Thu Nov 29 15:36:15 2012] [error] [client 94.40.46.28] unable to init Zlib: deflateInit2 returned -4: URL /charts/browser_pie.png
[Thu Nov 29 15:36:42 2012] [error] [client 94.40.46.28] mod_wsgi (pid=9369): Exception occurred processing WSGI script '/home/projects/canvastest/canvastest/wsgi.py'.
[Thu Nov 29 15:36:42 2012] [error] [client 94.40.46.28] Traceback (most recent call last):
[Thu Nov 29 15:36:42 2012] [error] [client 94.40.46.28]   File "/usr/lib/python2.7/dist-packages/django/core/handlers/wsgi.py", line 241, in __call__
[Thu Nov 29 15:36:42 2012] [error] [client 94.40.46.28]     response = self.get_response(request)
[Thu Nov 29 15:36:42 2012] [error] [client 94.40.46.28]   File "/usr/lib/python2.7/dist-packages/django/core/handlers/base.py", line 179, in get_response
[Thu Nov 29 15:36:42 2012] [error] [client 94.40.46.28]     response = self.handle_uncaught_exception(request, resolver, sys.exc_info())
[Thu Nov 29 15:36:42 2012] [error] [client 94.40.46.28]   File "/usr/lib/python2.7/dist-packages/django/core/handlers/base.py", line 221, in handle_uncaught_exception
[Thu Nov 29 15:36:42 2012] [error] [client 94.40.46.28]     return debug.technical_500_response(request, *exc_info)
[Thu Nov 29 15:36:42 2012] [error] [client 94.40.46.28]   File "/usr/lib/python2.7/dist-packages/django/views/debug.py", line 66, in technical_500_response
[Thu Nov 29 15:36:42 2012] [error] [client 94.40.46.28]     html = reporter.get_traceback_html()
[Thu Nov 29 15:36:42 2012] [error] [client 94.40.46.28]   File "/usr/lib/python2.7/dist-packages/django/views/debug.py", line 285, in get_traceback_html
[Thu Nov 29 15:36:42 2012] [error] [client 94.40.46.28]     t = Template(TECHNICAL_500_TEMPLATE, name='Technical 500 template')
[Thu Nov 29 15:36:42 2012] [error] [client 94.40.46.28]   File "/usr/lib/python2.7/dist-packages/django/template/base.py", line 119, in __init__
[Thu Nov 29 15:36:42 2012] [error] [client 94.40.46.28]     template_string = smart_unicode(template_string)
[Thu Nov 29 15:36:42 2012] [error] [client 94.40.46.28]   File "/usr/lib/python2.7/dist-packages/django/utils/encoding.py", line 39, in smart_unicode
[Thu Nov 29 15:36:42 2012] [error] [client 94.40.46.28] unable to init Zlib: deflateInit2 returned -4: URL /charts/browser_pie.png
[Thu Nov 29 15:36:44 2012] [error] [client 94.40.46.28] mod_wsgi (pid=9367): Exception occurred processing WSGI script '/home/projects/canvastest/canvastest/wsgi.py'.
[Thu Nov 29 15:36:44 2012] [error] [client 94.40.46.28] Traceback (most recent call last):
[Thu Nov 29 15:36:44 2012] [error] [client 94.40.46.28]   File "/usr/lib/python2.7/dist-packages/django/core/handlers/wsgi.py", line 241, in __call__
[Thu Nov 29 15:36:44 2012] [error] [client 94.40.46.28]     response = self.get_response(request)
[Thu Nov 29 15:36:44 2012] [error] [client 94.40.46.28]   File "/usr/lib/python2.7/dist-packages/django/core/handlers/base.py", line 179, in get_response
[Thu Nov 29 15:36:44 2012] [error] [client 94.40.46.28]     response = self.handle_uncaught_exception(request, resolver, sys.exc_info())
[Thu Nov 29 15:36:44 2012] [error] [client 94.40.46.28]   File "/usr/lib/python2.7/dist-packages/django/core/handlers/base.py", line 221, in handle_uncaught_exception
[Thu Nov 29 15:36:44 2012] [error] [client 94.40.46.28]     return debug.technical_500_response(request, *exc_info)
[Thu Nov 29 15:36:44 2012] [error] [client 94.40.46.28]   File "/usr/lib/python2.7/dist-packages/django/views/debug.py", line 66, in technical_500_response
[Thu Nov 29 15:36:44 2012] [error] [client 94.40.46.28] unable to init Zlib: deflateInit2 returned -4: URL /charts/browser_pie.png
[Thu Nov 29 15:36:45 2012] [error] [client 94.40.46.28] mod_wsgi (pid=9366): Exception occurred processing WSGI script '/home/projects/canvastest/canvastest/wsgi.py'.
[Thu Nov 29 15:36:45 2012] [error] [client 94.40.46.28] Traceback (most recent call last):
[Thu Nov 29 15:36:45 2012] [error] [client 94.40.46.28]   File "/usr/lib/python2.7/dist-packages/django/core/handlers/wsgi.py", line 241, in __call__
[Thu Nov 29 15:36:45 2012] [error] [client 94.40.46.28]     response = self.get_response(request)
[Thu Nov 29 15:36:45 2012] [error] [client 94.40.46.28]   File "/usr/lib/python2.7/dist-packages/django/core/handlers/base.py", line 179, in get_response
[Thu Nov 29 15:36:45 2012] [error] [client 94.40.46.28]     response = self.handle_uncaught_exception(request, resolver, sys.exc_info())
[Thu Nov 29 15:36:45 2012] [error] [client 94.40.46.28]   File "/usr/lib/python2.7/dist-packages/django/core/handlers/base.py", line 221, in handle_uncaught_exception
[Thu Nov 29 15:36:45 2012] [error] [client 94.40.46.28]     return debug.technical_500_response(request, *exc_info)
[Thu Nov 29 15:36:45 2012] [error] [client 94.40.46.28]   File "/usr/lib/python2.7/dist-packages/django/views/debug.py", line 66, in technical_500_response
[Thu Nov 29 15:36:45 2012] [error] [client 94.40.46.28] unable to init Zlib: deflateInit2 returned -4: URL /charts/browser_pie.png
[Thu Nov 29 15:36:45 2012] [error] [client 94.40.46.28] mod_wsgi (pid=9358): Exception occurred processing WSGI script '/home/projects/canvastest/canvastest/wsgi.py'.
[Thu Nov 29 15:36:45 2012] [error] [client 94.40.46.28] Traceback (most recent call last):
[Thu Nov 29 15:36:45 2012] [error] [client 94.40.46.28]   File "/usr/lib/python2.7/dist-packages/django/core/handlers/wsgi.py", line 241, in __call__
[Thu Nov 29 15:36:45 2012] [error] [client 94.40.46.28]     response = self.get_response(request)
[Thu Nov 29 15:36:45 2012] [error] [client 94.40.46.28]   File "/usr/lib/python2.7/dist-packages/django/core/handlers/base.py", line 179, in get_response
[Thu Nov 29 15:36:45 2012] [error] [client 94.40.46.28]     response = self.handle_uncaught_exception(request, resolver, sys.exc_info())
[Thu Nov 29 15:36:45 2012] [error] [client 94.40.46.28] MemoryError
[Thu Nov 29 15:36:45 2012] [error] [client 94.40.46.28] unable to init Zlib: deflateInit2 returned -4: URL /charts/browser_pie.png
[Thu Nov 29 15:36:46 2012] [error] [client 94.40.46.28] mod_wsgi (pid=9355): Exception occurred processing WSGI script '/home/projects/canvastest/canvastest/wsgi.py'.
[Thu Nov 29 15:36:46 2012] [error] [client 94.40.46.28] Traceback (most recent call last):
[Thu Nov 29 15:36:46 2012] [error] [client 94.40.46.28]   File "/usr/lib/python2.7/dist-packages/django/core/handlers/wsgi.py", line 241, in __call__
[Thu Nov 29 15:36:46 2012] [error] [client 94.40.46.28]     response = self.get_response(request)
[Thu Nov 29 15:36:46 2012] [error] [client 94.40.46.28]   File "/usr/lib/python2.7/dist-packages/django/core/handlers/base.py", line 179, in get_response
[Thu Nov 29 15:36:46 2012] [error] [client 94.40.46.28]     response = self.handle_uncaught_exception(request, resolver, sys.exc_info())
[Thu Nov 29 15:36:46 2012] [error] [client 94.40.46.28]   File "/usr/lib/python2.7/dist-packages/django/core/handlers/base.py", line 221, in handle_uncaught_exception
[Thu Nov 29 15:36:46 2012] [error] [client 94.40.46.28]     return debug.technical_500_response(request, *exc_info)
[Thu Nov 29 15:36:46 2012] [error] [client 94.40.46.28]   File "/usr/lib/python2.7/dist-packages/django/views/debug.py", line 66, in technical_500_response
[Thu Nov 29 15:36:46 2012] [error] [client 94.40.46.28]     html = reporter.get_traceback_html()
[Thu Nov 29 15:36:46 2012] [error] [client 94.40.46.28]   File "/usr/lib/python2.7/dist-packages/django/views/debug.py", line 285, in get_traceback_html
[Thu Nov 29 15:36:46 2012] [error] [client 94.40.46.28]     t = Template(TECHNICAL_500_TEMPLATE, name='Technical 500 template')
[Thu Nov 29 15:36:46 2012] [error] [client 94.40.46.28]   File "/usr/lib/python2.7/dist-packages/django/template/base.py", line 119, in __init__
[Thu Nov 29 15:36:46 2012] [error] [client 94.40.46.28] unable to init Zlib: deflateInit2 returned -4: URL /charts/browser_pie.png
[Thu Nov 29 15:36:47 2012] [error] [client 94.40.46.28] mod_wsgi (pid=9365): Exception occurred processing WSGI script '/home/projects/canvastest/canvastest/wsgi.py'.
[Thu Nov 29 15:36:47 2012] [error] [client 94.40.46.28] Traceback (most recent call last):
[Thu Nov 29 15:36:47 2012] [error] [client 94.40.46.28]   File "/usr/lib/python2.7/dist-packages/django/core/handlers/wsgi.py", line 243, in __call__
[Thu Nov 29 15:36:47 2012] [error] [client 94.40.46.28]     signals.request_finished.send(sender=self.__class__)
[Thu Nov 29 15:36:47 2012] [error] [client 94.40.46.28] unable to init Zlib: deflateInit2 returned -4: URL /charts/browser_pie.png
[Thu Nov 29 15:39:10 2012] [error] [client 94.40.46.28] mod_wsgi (pid=9368): Exception occurred processing WSGI script '/home/projects/canvastest/canvastest/wsgi.py'., referer: http://canvastest.leszniak.pl/
[Thu Nov 29 15:39:10 2012] [error] [client 94.40.46.28] Traceback (most recent call last):, referer: http://canvastest.leszniak.pl/
[Thu Nov 29 15:39:10 2012] [error] [client 94.40.46.28]   File "/usr/lib/python2.7/dist-packages/django/core/handlers/wsgi.py", line 241, in __call__, referer: http://canvastest.leszniak.pl/
[Thu Nov 29 15:39:10 2012] [error] [client 94.40.46.28]     response = self.get_response(request), referer: http://canvastest.leszniak.pl/
[Thu Nov 29 15:39:10 2012] [error] [client 94.40.46.28]   File "/usr/lib/python2.7/dist-packages/django/core/handlers/base.py", line 178, in get_response, referer: http://canvastest.leszniak.pl/
[Thu Nov 29 15:39:10 2012] [error] [client 94.40.46.28] unable to init Zlib: deflateInit2 returned -4: URL /charts/system_pie.png, referer: http://canvastest.leszniak.pl/
[Thu Nov 29 15:39:11 2012] [error] [client 94.40.46.28] mod_wsgi (pid=9352): Exception occurred processing WSGI script '/home/projects/canvastest/canvastest/wsgi.py'.
[Thu Nov 29 15:39:11 2012] [error] [client 94.40.46.28] Traceback (most recent call last):
[Thu Nov 29 15:39:11 2012] [error] [client 94.40.46.28]   File "/usr/lib/python2.7/dist-packages/django/core/handlers/wsgi.py", line 241, in __call__
[Thu Nov 29 15:39:11 2012] [error] [client 94.40.46.28]     response = self.get_response(request)
[Thu Nov 29 15:39:11 2012] [error] [client 94.40.46.28]   File "/usr/lib/python2.7/dist-packages/django/core/handlers/base.py", line 179, in get_response
[Thu Nov 29 15:39:11 2012] [error] [client 94.40.46.28]     response = self.handle_uncaught_exception(request, resolver, sys.exc_info())
[Thu Nov 29 15:39:11 2012] [error] [client 94.40.46.28]   File "/usr/lib/python2.7/dist-packages/django/core/handlers/base.py", line 215, in handle_uncaught_exception
[Thu Nov 29 15:39:11 2012] [error] [client 94.40.46.28]     'request': request
[Thu Nov 29 15:39:11 2012] [error] [client 94.40.46.28]   File "/usr/lib/python2.7/logging/__init__.py", line 1166, in error
[Thu Nov 29 15:39:11 2012] [error] [client 94.40.46.28]     self._log(ERROR, msg, args, **kwargs)
[Thu Nov 29 15:39:11 2012] [error] [client 94.40.46.28]   File "/usr/lib/python2.7/logging/__init__.py", line 1257, in _log
[Thu Nov 29 15:39:11 2012] [error] [client 94.40.46.28]     record = self.makeRecord(self.name, level, fn, lno, msg, args, exc_info, func, extra)
[Thu Nov 29 15:39:11 2012] [error] [client 94.40.46.28] MemoryError
[Thu Nov 29 15:39:11 2012] [error] [client 94.40.46.28] unable to init Zlib: deflateInit2 returned -4: URL /charts/browser_pie.png
[Thu Nov 29 15:39:13 2012] [error] [client 94.40.46.28] mod_wsgi (pid=9359): Exception occurred processing WSGI script '/home/projects/canvastest/canvastest/wsgi.py'.
[Thu Nov 29 15:39:13 2012] [error] [client 94.40.46.28] MemoryError
[Thu Nov 29 15:39:13 2012] [error] [client 94.40.46.28] unable to init Zlib: deflateInit2 returned -4: URL /charts/browser_pie.png
[Thu Nov 29 15:39:14 2012] [error] [client 94.40.46.28] mod_wsgi (pid=9357): Exception occurred processing WSGI script '/home/projects/canvastest/canvastest/wsgi.py'.
[Thu Nov 29 15:39:14 2012] [error] [client 94.40.46.28] Traceback (most recent call last):
[Thu Nov 29 15:39:14 2012] [error] [client 94.40.46.28]   File "/usr/lib/python2.7/dist-packages/django/core/handlers/wsgi.py", line 241, in __call__
[Thu Nov 29 15:39:14 2012] [error] [client 94.40.46.28]     response = self.get_response(request)
[Thu Nov 29 15:39:14 2012] [error] [client 94.40.46.28]   File "/usr/lib/python2.7/dist-packages/django/core/handlers/base.py", line 179, in get_response
[Thu Nov 29 15:39:14 2012] [error] [client 94.40.46.28]     response = self.handle_uncaught_exception(request, resolver, sys.exc_info())
[Thu Nov 29 15:39:14 2012] [error] [client 94.40.46.28]   File "/usr/lib/python2.7/dist-packages/django/core/handlers/base.py", line 221, in handle_uncaught_exception
[Thu Nov 29 15:39:14 2012] [error] [client 94.40.46.28]     return debug.technical_500_response(request, *exc_info)
[Thu Nov 29 15:39:14 2012] [error] [client 94.40.46.28]   File "/usr/lib/python2.7/dist-packages/django/views/debug.py", line 61, in technical_500_response
[Thu Nov 29 15:39:14 2012] [error] [client 94.40.46.28]   File "/usr/lib/python2.7/dist-packages/django/views/debug.py", line 208, in __init__
[Thu Nov 29 15:39:14 2012] [error] [client 94.40.46.28] unable to init Zlib: deflateInit2 returned -4: URL /charts/browser_pie.png
[Thu Nov 29 15:39:16 2012] [error] [client 94.40.46.28] mod_wsgi (pid=9534): Exception occurred processing WSGI script '/home/projects/canvastest/canvastest/wsgi.py'.
[Thu Nov 29 15:39:16 2012] [error] [client 94.40.46.28] Traceback (most recent call last):
[Thu Nov 29 15:39:16 2012] [error] [client 94.40.46.28]   File "/usr/lib/python2.7/dist-packages/django/core/handlers/wsgi.py", line 241, in __call__
[Thu Nov 29 15:39:16 2012] [error] [client 94.40.46.28]     response = self.get_response(request)
[Thu Nov 29 15:39:16 2012] [error] [client 94.40.46.28]   File "/usr/lib/python2.7/dist-packages/django/core/handlers/base.py", line 179, in get_response
[Thu Nov 29 15:39:16 2012] [error] [client 94.40.46.28]     response = self.handle_uncaught_exception(request, resolver, sys.exc_info())
[Thu Nov 29 15:39:16 2012] [error] [client 94.40.46.28] MemoryError
[Thu Nov 29 15:39:16 2012] [error] [client 94.40.46.28] unable to init Zlib: deflateInit2 returned -4: URL /charts/browser_pie.png
[Thu Nov 29 15:39:17 2012] [error] [client 94.40.46.28] mod_wsgi (pid=9364): Exception occurred processing WSGI script '/home/projects/canvastest/canvastest/wsgi.py'.
[Thu Nov 29 15:39:17 2012] [error] [client 94.40.46.28] Traceback (most recent call last):
[Thu Nov 29 15:39:17 2012] [error] [client 94.40.46.28]   File "/usr/lib/python2.7/dist-packages/django/core/handlers/wsgi.py", line 241, in __call__
[Thu Nov 29 15:39:17 2012] [error] [client 94.40.46.28]     response = self.get_response(request)
[Thu Nov 29 15:39:17 2012] [error] [client 94.40.46.28]   File "/usr/lib/python2.7/dist-packages/django/core/handlers/base.py", line 179, in get_response
[Thu Nov 29 15:39:17 2012] [error] [client 94.40.46.28]     response = self.handle_uncaught_exception(request, resolver, sys.exc_info())
[Thu Nov 29 15:39:17 2012] [error] [client 94.40.46.28]   File "/usr/lib/python2.7/dist-packages/django/core/handlers/base.py", line 221, in handle_uncaught_exception
[Thu Nov 29 15:39:17 2012] [error] [client 94.40.46.28]     return debug.technical_500_response(request, *exc_info)
[Thu Nov 29 15:39:17 2012] [error] [client 94.40.46.28]   File "/usr/lib/python2.7/dist-packages/django/views/debug.py", line 66, in technical_500_response
[Thu Nov 29 15:39:17 2012] [error] [client 94.40.46.28]     html = reporter.get_traceback_html()
[Thu Nov 29 15:39:17 2012] [error] [client 94.40.46.28]   File "/usr/lib/python2.7/dist-packages/django/views/debug.py", line 285, in get_traceback_html
[Thu Nov 29 15:39:17 2012] [error] [client 94.40.46.28]     t = Template(TECHNICAL_500_TEMPLATE, name='Technical 500 template')
[Thu Nov 29 15:39:17 2012] [error] [client 94.40.46.28]   File "/usr/lib/python2.7/dist-packages/django/template/base.py", line 119, in __init__
[Thu Nov 29 15:39:17 2012] [error] [client 94.40.46.28]     template_string = smart_unicode(template_string)
[Thu Nov 29 15:39:17 2012] [error] [client 94.40.46.28]   File "/usr/lib/python2.7/dist-packages/django/utils/encoding.py", line 39, in smart_unicode
[Thu Nov 29 15:39:17 2012] [error] [client 94.40.46.28]     return force_unicode(s, encoding, strings_only, errors)
[Thu Nov 29 15:39:17 2012] [error] [client 94.40.46.28]   File "/usr/lib/python2.7/dist-packages/django/utils/encoding.py", line 90, in force_unicode
[Thu Nov 29 15:39:17 2012] [error] [client 94.40.46.28]     s = s.decode(encoding, errors)
[Thu Nov 29 15:39:17 2012] [error] [client 94.40.46.28]   File "/usr/lib/python2.7/encodings/utf_8.py", line 16, in decode
[Thu Nov 29 15:39:17 2012] [error] [client 94.40.46.28]     return codecs.utf_8_decode(input, errors, True)
[Thu Nov 29 15:39:17 2012] [error] [client 94.40.46.28] MemoryError
[Thu Nov 29 15:39:17 2012] [error] [client 94.40.46.28] unable to init Zlib: deflateInit2 returned -4: URL /charts/browser_pie.png
[Thu Nov 29 15:39:17 2012] [error] [client 94.40.46.28] mod_wsgi (pid=9363): Exception occurred processing WSGI script '/home/projects/canvastest/canvastest/wsgi.py'.
[Thu Nov 29 15:39:17 2012] [error] [client 94.40.46.28] Traceback (most recent call last):
[Thu Nov 29 15:39:17 2012] [error] [client 94.40.46.28]   File "/usr/lib/python2.7/dist-packages/django/core/handlers/wsgi.py", line 241, in __call__
[Thu Nov 29 15:39:17 2012] [error] [client 94.40.46.28]     response = self.get_response(request)
[Thu Nov 29 15:39:17 2012] [error] [client 94.40.46.28]   File "/usr/lib/python2.7/dist-packages/django/core/handlers/base.py", line 179, in get_response
[Thu Nov 29 15:39:17 2012] [error] [client 94.40.46.28]     response = self.handle_uncaught_exception(request, resolver, sys.exc_info())
[Thu Nov 29 15:39:17 2012] [error] [client 94.40.46.28] MemoryError
[Thu Nov 29 15:39:17 2012] [error] [client 94.40.46.28] unable to init Zlib: deflateInit2 returned -4: URL /charts/browser_pie.png
[Thu Nov 29 15:39:18 2012] [error] [client 94.40.46.28] mod_wsgi (pid=9362): Exception occurred processing WSGI script '/home/projects/canvastest/canvastest/wsgi.py'.
[Thu Nov 29 15:39:18 2012] [error] [client 94.40.46.28] Traceback (most recent call last):
[Thu Nov 29 15:39:18 2012] [error] [client 94.40.46.28]   File "/usr/lib/python2.7/dist-packages/django/core/handlers/wsgi.py", line 241, in __call__
[Thu Nov 29 15:39:18 2012] [error] [client 94.40.46.28]     response = self.get_response(request)
[Thu Nov 29 15:39:18 2012] [error] [client 94.40.46.28]   File "/usr/lib/python2.7/dist-packages/django/core/handlers/base.py", line 178, in get_response
[Thu Nov 29 15:39:18 2012] [error] [client 94.40.46.28]     signals.got_request_exception.send(sender=self.__class__, request=request)
[Thu Nov 29 15:39:18 2012] [error] [client 94.40.46.28] MemoryError
[Thu Nov 29 15:39:18 2012] [error] [client 94.40.46.28] unable to init Zlib: deflateInit2 returned -4: URL /charts/browser_pie.png
[Thu Nov 29 15:39:19 2012] [error] [client 94.40.46.28] mod_wsgi (pid=9370): Exception occurred processing WSGI script '/home/projects/canvastest/canvastest/wsgi.py'.
[Thu Nov 29 15:39:19 2012] [error] [client 94.40.46.28] Traceback (most recent call last):
[Thu Nov 29 15:39:19 2012] [error] [client 94.40.46.28]   File "/usr/lib/python2.7/dist-packages/django/core/handlers/wsgi.py", line 241, in __call__
[Thu Nov 29 15:39:19 2012] [error] [client 94.40.46.28]     response = self.get_response(request)
[Thu Nov 29 15:39:19 2012] [error] [client 94.40.46.28]   File "/usr/lib/python2.7/dist-packages/django/core/handlers/base.py", line 179, in get_response
[Thu Nov 29 15:39:19 2012] [error] [client 94.40.46.28]     response = self.handle_uncaught_exception(request, resolver, sys.exc_info())
[Thu Nov 29 15:39:19 2012] [error] [client 94.40.46.28]   File "/usr/lib/python2.7/dist-packages/django/core/handlers/base.py", line 221, in handle_uncaught_exception
[Thu Nov 29 15:39:19 2012] [error] [client 94.40.46.28]     return debug.technical_500_response(request, *exc_info)
[Thu Nov 29 15:39:19 2012] [error] [client 94.40.46.28]   File "/usr/lib/python2.7/dist-packages/django/views/debug.py", line 66, in technical_500_response
[Thu Nov 29 15:39:19 2012] [error] [client 94.40.46.28]     html = reporter.get_traceback_html()
[Thu Nov 29 15:39:19 2012] [error] [client 94.40.46.28]   File "/usr/lib/python2.7/dist-packages/django/views/debug.py", line 285, in get_traceback_html
[Thu Nov 29 15:39:19 2012] [error] [client 94.40.46.28]     t = Template(TECHNICAL_500_TEMPLATE, name='Technical 500 template')
[Thu Nov 29 15:39:19 2012] [error] [client 94.40.46.28]   File "/usr/lib/python2.7/dist-packages/django/template/base.py", line 119, in __init__
[Thu Nov 29 15:39:19 2012] [error] [client 94.40.46.28] unable to init Zlib: deflateInit2 returned -4: URL /charts/browser_pie.png
[Thu Nov 29 15:39:19 2012] [error] [client 94.40.46.28] mod_wsgi (pid=9367): Exception occurred processing WSGI script '/home/projects/canvastest/canvastest/wsgi.py'.
[Thu Nov 29 15:39:19 2012] [error] [client 94.40.46.28] unable to init Zlib: deflateInit2 returned -4: URL /charts/browser_pie.png
[Thu Nov 29 15:39:19 2012] [error] [client 94.40.46.28] mod_wsgi (pid=9358): Exception occurred processing WSGI script '/home/projects/canvastest/canvastest/wsgi.py'.
[Thu Nov 29 15:39:19 2012] [error] [client 94.40.46.28] Traceback (most recent call last):
[Thu Nov 29 15:39:19 2012] [error] [client 94.40.46.28]   File "/usr/lib/python2.7/dist-packages/django/core/handlers/wsgi.py", line 241, in __call__
[Thu Nov 29 15:39:19 2012] [error] [client 94.40.46.28]     response = self.get_response(request)
[Thu Nov 29 15:39:19 2012] [error] [client 94.40.46.28]   File "/usr/lib/python2.7/dist-packages/django/core/handlers/base.py", line 179, in get_response
[Thu Nov 29 15:39:19 2012] [error] [client 94.40.46.28]     response = self.handle_uncaught_exception(request, resolver, sys.exc_info())
[Thu Nov 29 15:39:19 2012] [error] [client 94.40.46.28]   File "/usr/lib/python2.7/dist-packages/django/core/handlers/base.py", line 221, in handle_uncaught_exception
[Thu Nov 29 15:39:19 2012] [error] [client 94.40.46.28]     return debug.technical_500_response(request, *exc_info)
[Thu Nov 29 15:39:19 2012] [error] [client 94.40.46.28]   File "/usr/lib/python2.7/dist-packages/django/views/debug.py", line 66, in technical_500_response
[Thu Nov 29 15:39:19 2012] [error] [client 94.40.46.28]     html = reporter.get_traceback_html()
[Thu Nov 29 15:39:19 2012] [error] [client 94.40.46.28]   File "/usr/lib/python2.7/dist-packages/django/views/debug.py", line 285, in get_traceback_html
[Thu Nov 29 15:39:19 2012] [error] [client 94.40.46.28]     t = Template(TECHNICAL_500_TEMPLATE, name='Technical 500 template')
[Thu Nov 29 15:39:19 2012] [error] [client 94.40.46.28]   File "/usr/lib/python2.7/dist-packages/django/template/base.py", line 119, in __init__
[Thu Nov 29 15:39:19 2012] [error] [client 94.40.46.28] unable to init Zlib: deflateInit2 returned -4: URL /charts/browser_pie.png
[Thu Nov 29 15:39:19 2012] [error] [client 94.40.46.28] mod_wsgi (pid=9355): Exception occurred processing WSGI script '/home/projects/canvastest/canvastest/wsgi.py'.
[Thu Nov 29 15:39:19 2012] [error] [client 94.40.46.28] Traceback (most recent call last):
[Thu Nov 29 15:39:19 2012] [error] [client 94.40.46.28]   File "/usr/lib/python2.7/dist-packages/django/core/handlers/wsgi.py", line 241, in __call__
[Thu Nov 29 15:39:19 2012] [error] [client 94.40.46.28]     response = self.get_response(request)
[Thu Nov 29 15:39:19 2012] [error] [client 94.40.46.28]   File "/usr/lib/python2.7/dist-packages/django/core/handlers/base.py", line 179, in get_response
[Thu Nov 29 15:39:19 2012] [error] [client 94.40.46.28]     response = self.handle_uncaught_exception(request, resolver, sys.exc_info())
[Thu Nov 29 15:39:19 2012] [error] [client 94.40.46.28]   File "/usr/lib/python2.7/dist-packages/django/core/handlers/base.py", line 221, in handle_uncaught_exception
[Thu Nov 29 15:39:19 2012] [error] [client 94.40.46.28]     return debug.technical_500_response(request, *exc_info)
[Thu Nov 29 15:39:19 2012] [error] [client 94.40.46.28]   File "/usr/lib/python2.7/dist-packages/django/views/debug.py", line 66, in technical_500_response
[Thu Nov 29 15:39:19 2012] [error] [client 94.40.46.28]     html = reporter.get_traceback_html()
[Thu Nov 29 15:39:19 2012] [error] [client 94.40.46.28]   File "/usr/lib/python2.7/dist-packages/django/views/debug.py", line 285, in get_traceback_html
[Thu Nov 29 15:39:19 2012] [error] [client 94.40.46.28]     t = Template(TECHNICAL_500_TEMPLATE, name='Technical 500 template')
[Thu Nov 29 15:39:19 2012] [error] [client 94.40.46.28]   File "/usr/lib/python2.7/dist-packages/django/template/base.py", line 119, in __init__
[Thu Nov 29 15:39:19 2012] [error] [client 94.40.46.28]     template_string = smart_unicode(template_string)
[Thu Nov 29 15:39:19 2012] [error] [client 94.40.46.28]   File "/usr/lib/python2.7/dist-packages/django/utils/encoding.py", line 39, in smart_unicode
[Thu Nov 29 15:39:19 2012] [error] [client 94.40.46.28]     return force_unicode(s, encoding, strings_only, errors)
[Thu Nov 29 15:39:19 2012] [error] [client 94.40.46.28]   File "/usr/lib/python2.7/dist-packages/django/utils/encoding.py", line 90, in force_unicode
[Thu Nov 29 15:39:19 2012] [error] [client 94.40.46.28]     s = s.decode(encoding, errors)
[Thu Nov 29 15:39:19 2012] [error] [client 94.40.46.28]   File "/usr/lib/python2.7/encodings/utf_8.py", line 16, in decode
[Thu Nov 29 15:39:19 2012] [error] [client 94.40.46.28]     return codecs.utf_8_decode(input, errors, True)
[Thu Nov 29 15:39:19 2012] [error] [client 94.40.46.28] unable to init Zlib: deflateInit2 returned -4: URL /charts/browser_pie.png
[Thu Nov 29 15:39:19 2012] [error] [client 94.40.46.28] mod_wsgi (pid=9365): Exception occurred processing WSGI script '/home/projects/canvastest/canvastest/wsgi.py'.
[Thu Nov 29 15:39:19 2012] [error] [client 94.40.46.28] Traceback (most recent call last):
[Thu Nov 29 15:39:19 2012] [error] [client 94.40.46.28]   File "/usr/lib/python2.7/dist-packages/django/core/handlers/wsgi.py", line 241, in __call__
[Thu Nov 29 15:39:19 2012] [error] [client 94.40.46.28]     response = self.get_response(request)
[Thu Nov 29 15:39:19 2012] [error] [client 94.40.46.28]   File "/usr/lib/python2.7/dist-packages/django/core/handlers/base.py", line 179, in get_response
[Thu Nov 29 15:39:19 2012] [error] [client 94.40.46.28]     response = self.handle_uncaught_exception(request, resolver, sys.exc_info())
[Thu Nov 29 15:39:19 2012] [error] [client 94.40.46.28]   File "/usr/lib/python2.7/dist-packages/django/core/handlers/base.py", line 221, in handle_uncaught_exception
[Thu Nov 29 15:39:19 2012] [error] [client 94.40.46.28]     return debug.technical_500_response(request, *exc_info)
[Thu Nov 29 15:39:19 2012] [error] [client 94.40.46.28]   File "/usr/lib/python2.7/dist-packages/django/views/debug.py", line 66, in technical_500_response
[Thu Nov 29 15:39:19 2012] [error] [client 94.40.46.28] unable to init Zlib: deflateInit2 returned -4: URL /charts/browser_pie.png
[Thu Nov 29 15:39:20 2012] [error] [client 94.40.46.28] mod_wsgi (pid=9360): Exception occurred processing WSGI script '/home/projects/canvastest/canvastest/wsgi.py'.
[Thu Nov 29 15:39:20 2012] [error] [client 94.40.46.28] Traceback (most recent call last):
[Thu Nov 29 15:39:20 2012] [error] [client 94.40.46.28]   File "/usr/lib/python2.7/dist-packages/django/core/handlers/wsgi.py", line 241, in __call__
[Thu Nov 29 15:39:20 2012] [error] [client 94.40.46.28]     response = self.get_response(request)
[Thu Nov 29 15:39:20 2012] [error] [client 94.40.46.28]   File "/usr/lib/python2.7/dist-packages/django/core/handlers/base.py", line 179, in get_response
[Thu Nov 29 15:39:20 2012] [error] [client 94.40.46.28]     response = self.handle_uncaught_exception(request, resolver, sys.exc_info())
[Thu Nov 29 15:39:20 2012] [error] [client 94.40.46.28]   File "/usr/lib/python2.7/dist-packages/django/core/handlers/base.py", line 221, in handle_uncaught_exception
[Thu Nov 29 15:39:20 2012] [error] [client 94.40.46.28]     return debug.technical_500_response(request, *exc_info)
[Thu Nov 29 15:39:20 2012] [error] [client 94.40.46.28]   File "/usr/lib/python2.7/dist-packages/django/views/debug.py", line 66, in technical_500_response
[Thu Nov 29 15:39:20 2012] [error] [client 94.40.46.28]     html = reporter.get_traceback_html()
[Thu Nov 29 15:39:20 2012] [error] [client 94.40.46.28]   File "/usr/lib/python2.7/dist-packages/django/views/debug.py", line 285, in get_traceback_html
[Thu Nov 29 15:39:20 2012] [error] [client 94.40.46.28]     t = Template(TECHNICAL_500_TEMPLATE, name='Technical 500 template')
[Thu Nov 29 15:39:20 2012] [error] [client 94.40.46.28]   File "/usr/lib/python2.7/dist-packages/django/template/base.py", line 125, in __init__
[Thu Nov 29 15:39:20 2012] [error] [client 94.40.46.28]     self.nodelist = compile_string(template_string, origin)
[Thu Nov 29 15:39:20 2012] [error] [client 94.40.46.28]   File "/usr/lib/python2.7/dist-packages/django/template/base.py", line 152, in compile_string
[Thu Nov 29 15:39:20 2012] [error] [client 94.40.46.28]     parser = parser_class(lexer.tokenize())
[Thu Nov 29 15:39:20 2012] [error] [client 94.40.46.28]   File "/usr/lib/python2.7/dist-packages/django/template/debug.py", line 19, in tokenize
[Thu Nov 29 15:39:20 2012] [error] [client 94.40.46.28]     result.append(self.create_token(self.template_string[upto:start], (upto, start), False))
[Thu Nov 29 15:39:20 2012] [error] [client 94.40.46.28] MemoryError
[Thu Nov 29 15:39:20 2012] [error] [client 94.40.46.28] unable to init Zlib: deflateInit2 returned -4: URL /charts/browser_pie.png
[Thu Nov 29 15:39:21 2012] [error] [client 94.40.46.28] mod_wsgi (pid=9361): Exception occurred processing WSGI script '/home/projects/canvastest/canvastest/wsgi.py'.
[Thu Nov 29 15:39:21 2012] [error] [client 94.40.46.28] IOError: failed to write data
[Thu Nov 29 15:39:55 2012] [error] [client 94.40.46.28] mod_wsgi (pid=9534): Exception occurred processing WSGI script '/home/projects/canvastest/canvastest/wsgi.py'.
[Thu Nov 29 15:39:55 2012] [error] [client 94.40.46.28] Traceback (most recent call last):
[Thu Nov 29 15:39:55 2012] [error] [client 94.40.46.28]   File "/usr/lib/python2.7/dist-packages/django/core/handlers/wsgi.py", line 241, in __call__
[Thu Nov 29 15:39:55 2012] [error] [client 94.40.46.28]     response = self.get_response(request)
[Thu Nov 29 15:39:55 2012] [error] [client 94.40.46.28]   File "/usr/lib/python2.7/dist-packages/django/core/handlers/base.py", line 178, in get_response
[Thu Nov 29 15:39:55 2012] [error] [client 94.40.46.28]     signals.got_request_exception.send(sender=self.__class__, request=request)
[Thu Nov 29 15:39:55 2012] [error] [client 94.40.46.28]   File "/usr/lib/python2.7/dist-packages/django/dispatch/dispatcher.py", line 172, in send
[Thu Nov 29 15:39:55 2012] [error] [client 94.40.46.28]     response = receiver(signal=self, sender=sender, **named)
[Thu Nov 29 15:39:55 2012] [error] [client 94.40.46.28]   File "/usr/lib/python2.7/dist-packages/django/db/__init__.py", line 62, in _rollback_on_exception
[Thu Nov 29 15:39:55 2012] [error] [client 94.40.46.28]     transaction.rollback_unless_managed(using=conn)
[Thu Nov 29 15:39:55 2012] [error] [client 94.40.46.28]   File "/usr/lib/python2.7/dist-packages/django/db/transaction.py", line 129, in rollback_unless_managed
[Thu Nov 29 15:39:55 2012] [error] [client 94.40.46.28]     connection.rollback_unless_managed()
[Thu Nov 29 15:39:55 2012] [error] [client 94.40.46.28]   File "/usr/lib/python2.7/dist-packages/django/db/backends/__init__.py", line 214, in rollback_unless_managed
[Thu Nov 29 15:39:55 2012] [error] [client 94.40.46.28] unable to init Zlib: deflateInit2 returned -4: URL /charts/browser_pie.png
[Thu Nov 29 15:40:38 2012] [error] [client 94.40.46.28] mod_wsgi (pid=9353): Exception occurred processing WSGI script '/home/projects/canvastest/canvastest/wsgi.py'.
[Thu Nov 29 15:40:38 2012] [error] [client 94.40.46.28] IOError: failed to write data
[Fri Nov 30 00:54:44 2012] [error] [client 83.12.83.178] mod_wsgi (pid=9955): Exception occurred processing WSGI script '/home/projects/canvastest/canvastest/wsgi.py'.
[Fri Nov 30 00:54:44 2012] [error] [client 83.12.83.178] Traceback (most recent call last):
[Fri Nov 30 00:54:44 2012] [error] [client 83.12.83.178]   File "/usr/lib/python2.7/dist-packages/django/core/handlers/wsgi.py", line 241, in __call__
[Fri Nov 30 00:54:44 2012] [error] [client 83.12.83.178]     response = self.get_response(request)
[Fri Nov 30 00:54:44 2012] [error] [client 83.12.83.178]   File "/usr/lib/python2.7/dist-packages/django/core/handlers/base.py", line 179, in get_response
[Fri Nov 30 00:54:44 2012] [error] [client 83.12.83.178]     response = self.handle_uncaught_exception(request, resolver, sys.exc_info())
[Fri Nov 30 00:54:44 2012] [error] [client 83.12.83.178]   File "/usr/lib/python2.7/dist-packages/django/core/handlers/base.py", line 221, in handle_uncaught_exception
[Fri Nov 30 00:54:44 2012] [error] [client 83.12.83.178]     return debug.technical_500_response(request, *exc_info)
[Fri Nov 30 00:54:44 2012] [error] [client 83.12.83.178]   File "/usr/lib/python2.7/dist-packages/django/views/debug.py", line 66, in technical_500_response
[Fri Nov 30 00:54:44 2012] [error] [client 83.12.83.178]     html = reporter.get_traceback_html()
[Fri Nov 30 00:54:44 2012] [error] [client 83.12.83.178]   File "/usr/lib/python2.7/dist-packages/django/views/debug.py", line 287, in get_traceback_html
[Fri Nov 30 00:54:44 2012] [error] [client 83.12.83.178]     return t.render(c)
[Fri Nov 30 00:54:44 2012] [error] [client 83.12.83.178]   File "/usr/lib/python2.7/dist-packages/django/template/base.py", line 140, in render
[Fri Nov 30 00:54:44 2012] [error] [client 83.12.83.178]     return self._render(context)
[Fri Nov 30 00:54:44 2012] [error] [client 83.12.83.178]   File "/usr/lib/python2.7/dist-packages/django/template/base.py", line 134, in _render
[Fri Nov 30 00:54:44 2012] [error] [client 83.12.83.178]     return self.nodelist.render(context)
[Fri Nov 30 00:54:44 2012] [error] [client 83.12.83.178]   File "/usr/lib/python2.7/dist-packages/django/template/base.py", line 827, in render
[Fri Nov 30 00:54:44 2012] [error] [client 83.12.83.178]     return mark_safe(u''.join(bits))
[Fri Nov 30 00:54:44 2012] [error] [client 83.12.83.178] MemoryError
[Fri Nov 30 00:54:44 2012] [error] [client 83.12.83.178] mod_wsgi (pid=15718): Exception occurred processing WSGI script '/home/projects/canvastest/canvastest/wsgi.py'.
[Fri Nov 30 00:54:44 2012] [error] [client 83.12.83.178] IOError: failed to write data
[Fri Nov 30 01:27:29 2012] [error] [client 46.248.160.248] mod_wsgi (pid=16123): Exception occurred processing WSGI script '/home/projects/canvastest/canvastest/wsgi.py'.
[Fri Nov 30 01:27:29 2012] [error] [client 46.248.160.248] unable to init Zlib: deflateInit2 returned -4: URL /wyszukaj
[Fri Nov 30 01:27:31 2012] [error] [client 46.248.160.248] unable to init Zlib: deflateInit2 returned -4: URL /wyszukaj
[Fri Nov 30 01:27:37 2012] [error] [client 46.248.160.248] mod_wsgi (pid=16119): Exception occurred processing WSGI script '/home/projects/canvastest/canvastest/wsgi.py'., referer: http://canvastest.leszniak.pl/wyszukaj
[Fri Nov 30 01:27:37 2012] [error] [client 46.248.160.248] Traceback (most recent call last):, referer: http://canvastest.leszniak.pl/wyszukaj
[Fri Nov 30 01:27:37 2012] [error] [client 46.248.160.248]   File "/usr/lib/python2.7/dist-packages/django/core/handlers/wsgi.py", line 241, in __call__, referer: http://canvastest.leszniak.pl/wyszukaj
[Fri Nov 30 01:27:37 2012] [error] [client 46.248.160.248]     response = self.get_response(request), referer: http://canvastest.leszniak.pl/wyszukaj
[Fri Nov 30 01:27:37 2012] [error] [client 46.248.160.248]   File "/usr/lib/python2.7/dist-packages/django/core/handlers/base.py", line 178, in get_response, referer: http://canvastest.leszniak.pl/wyszukaj
[Fri Nov 30 01:27:37 2012] [error] [client 46.248.160.248]     signals.got_request_exception.send(sender=self.__class__, request=request), referer: http://canvastest.leszniak.pl/wyszukaj
[Fri Nov 30 01:27:37 2012] [error] [client 46.248.160.248]   File "/usr/lib/python2.7/dist-packages/django/dispatch/dispatcher.py", line 172, in send, referer: http://canvastest.leszniak.pl/wyszukaj
[Fri Nov 30 01:27:37 2012] [error] [client 46.248.160.248]     response = receiver(signal=self, sender=sender, **named), referer: http://canvastest.leszniak.pl/wyszukaj
[Fri Nov 30 01:27:37 2012] [error] [client 46.248.160.248]   File "/usr/lib/python2.7/dist-packages/django/db/__init__.py", line 62, in _rollback_on_exception, referer: http://canvastest.leszniak.pl/wyszukaj
[Fri Nov 30 01:27:37 2012] [error] [client 46.248.160.248]     transaction.rollback_unless_managed(using=conn), referer: http://canvastest.leszniak.pl/wyszukaj
[Fri Nov 30 01:27:37 2012] [error] [client 46.248.160.248]   File "/usr/lib/python2.7/dist-packages/django/db/transaction.py", line 129, in rollback_unless_managed, referer: http://canvastest.leszniak.pl/wyszukaj
[Fri Nov 30 01:27:37 2012] [error] [client 46.248.160.248]     connection.rollback_unless_managed(), referer: http://canvastest.leszniak.pl/wyszukaj
[Fri Nov 30 01:27:37 2012] [error] [client 46.248.160.248]   File "/usr/lib/python2.7/dist-packages/django/db/backends/__init__.py", line 214, in rollback_unless_managed, referer: http://canvastest.leszniak.pl/wyszukaj
[Fri Nov 30 01:27:37 2012] [error] [client 46.248.160.248]     self._rollback(), referer: http://canvastest.leszniak.pl/wyszukaj
[Fri Nov 30 01:27:37 2012] [error] [client 46.248.160.248]   File "/usr/lib/python2.7/dist-packages/django/db/backends/mysql/base.py", line 404, in _rollback, referer: http://canvastest.leszniak.pl/wyszukaj
[Fri Nov 30 01:27:37 2012] [error] [client 46.248.160.248]     BaseDatabaseWrapper._rollback(self), referer: http://canvastest.leszniak.pl/wyszukaj
[Fri Nov 30 01:27:37 2012] [error] [client 46.248.160.248] MemoryError, referer: http://canvastest.leszniak.pl/wyszukaj
[Fri Nov 30 01:27:37 2012] [error] [client 46.248.160.248] unable to init Zlib: deflateInit2 returned -4: URL /wyszukaj, referer: http://canvastest.leszniak.pl/wyszukaj
[Fri Nov 30 01:27:40 2012] [error] [client 46.248.160.248] unable to init Zlib: deflateInit2 returned -4: URL /wyszukaj
[Fri Nov 30 01:27:48 2012] [error] [client 46.248.160.248] mod_wsgi (pid=16108): Exception occurred processing WSGI script '/home/projects/canvastest/canvastest/wsgi.py'., referer: http://canvastest.leszniak.pl/wyszukaj
[Fri Nov 30 01:27:48 2012] [error] [client 46.248.160.248] Traceback (most recent call last):, referer: http://canvastest.leszniak.pl/wyszukaj
[Fri Nov 30 01:27:48 2012] [error] [client 46.248.160.248]   File "/usr/lib/python2.7/dist-packages/django/core/handlers/wsgi.py", line 241, in __call__, referer: http://canvastest.leszniak.pl/wyszukaj
[Fri Nov 30 01:27:48 2012] [error] [client 46.248.160.248]     response = self.get_response(request), referer: http://canvastest.leszniak.pl/wyszukaj
[Fri Nov 30 01:27:48 2012] [error] [client 46.248.160.248]   File "/usr/lib/python2.7/dist-packages/django/core/handlers/base.py", line 179, in get_response, referer: http://canvastest.leszniak.pl/wyszukaj
[Fri Nov 30 01:27:48 2012] [error] [client 46.248.160.248]     response = self.handle_uncaught_exception(request, resolver, sys.exc_info()), referer: http://canvastest.leszniak.pl/wyszukaj
[Fri Nov 30 01:27:48 2012] [error] [client 46.248.160.248]   File "/usr/lib/python2.7/dist-packages/django/core/handlers/base.py", line 221, in handle_uncaught_exception, referer: http://canvastest.leszniak.pl/wyszukaj
[Fri Nov 30 01:27:48 2012] [error] [client 46.248.160.248]     return debug.technical_500_response(request, *exc_info), referer: http://canvastest.leszniak.pl/wyszukaj
[Fri Nov 30 01:27:48 2012] [error] [client 46.248.160.248]   File "/usr/lib/python2.7/dist-packages/django/views/debug.py", line 66, in technical_500_response, referer: http://canvastest.leszniak.pl/wyszukaj
[Fri Nov 30 01:27:48 2012] [error] [client 46.248.160.248]     html = reporter.get_traceback_html(), referer: http://canvastest.leszniak.pl/wyszukaj
[Fri Nov 30 01:27:48 2012] [error] [client 46.248.160.248]   File "/usr/lib/python2.7/dist-packages/django/views/debug.py", line 285, in get_traceback_html, referer: http://canvastest.leszniak.pl/wyszukaj
[Fri Nov 30 01:27:48 2012] [error] [client 46.248.160.248]     t = Template(TECHNICAL_500_TEMPLATE, name='Technical 500 template'), referer: http://canvastest.leszniak.pl/wyszukaj
[Fri Nov 30 01:27:48 2012] [error] [client 46.248.160.248]   File "/usr/lib/python2.7/dist-packages/django/template/base.py", line 119, in __init__, referer: http://canvastest.leszniak.pl/wyszukaj
[Fri Nov 30 01:27:48 2012] [error] [client 46.248.160.248] unable to init Zlib: deflateInit2 returned -4: URL /wyszukaj, referer: http://canvastest.leszniak.pl/wyszukaj
[Fri Nov 30 01:28:19 2012] [error] [client 46.248.160.248] mod_wsgi (pid=16121): Exception occurred processing WSGI script '/home/projects/canvastest/canvastest/wsgi.py'., referer: http://canvastest.leszniak.pl/wyszukaj
[Fri Nov 30 01:28:19 2012] [error] [client 46.248.160.248] Traceback (most recent call last):, referer: http://canvastest.leszniak.pl/wyszukaj
[Fri Nov 30 01:28:19 2012] [error] [client 46.248.160.248]   File "/usr/lib/python2.7/dist-packages/django/core/handlers/wsgi.py", line 241, in __call__, referer: http://canvastest.leszniak.pl/wyszukaj
[Fri Nov 30 01:28:19 2012] [error] [client 46.248.160.248] unable to init Zlib: deflateInit2 returned -4: URL /charts/simple.png44, referer: http://canvastest.leszniak.pl/wyszukaj
[Fri Nov 30 01:28:32 2012] [error] [client 46.248.160.248] mod_wsgi (pid=16104): Exception occurred processing WSGI script '/home/projects/canvastest/canvastest/wsgi.py'., referer: http://canvastest.leszniak.pl/wyszukaj
[Fri Nov 30 01:28:32 2012] [error] [client 46.248.160.248] Traceback (most recent call last):, referer: http://canvastest.leszniak.pl/wyszukaj
[Fri Nov 30 01:28:32 2012] [error] [client 46.248.160.248]   File "/usr/lib/python2.7/dist-packages/django/core/handlers/wsgi.py", line 241, in __call__, referer: http://canvastest.leszniak.pl/wyszukaj
[Fri Nov 30 01:28:32 2012] [error] [client 46.248.160.248]     response = self.get_response(request), referer: http://canvastest.leszniak.pl/wyszukaj
[Fri Nov 30 01:28:32 2012] [error] [client 46.248.160.248]   File "/usr/lib/python2.7/dist-packages/django/core/handlers/base.py", line 178, in get_response, referer: http://canvastest.leszniak.pl/wyszukaj
[Fri Nov 30 01:28:32 2012] [error] [client 46.248.160.248]     signals.got_request_exception.send(sender=self.__class__, request=request), referer: http://canvastest.leszniak.pl/wyszukaj
[Fri Nov 30 01:28:32 2012] [error] [client 46.248.160.248]   File "/usr/lib/python2.7/dist-packages/django/dispatch/dispatcher.py", line 172, in send, referer: http://canvastest.leszniak.pl/wyszukaj
[Fri Nov 30 01:28:32 2012] [error] [client 46.248.160.248]     response = receiver(signal=self, sender=sender, **named), referer: http://canvastest.leszniak.pl/wyszukaj
[Fri Nov 30 01:28:32 2012] [error] [client 46.248.160.248]   File "/usr/lib/python2.7/dist-packages/django/db/__init__.py", line 62, in _rollback_on_exception, referer: http://canvastest.leszniak.pl/wyszukaj
[Fri Nov 30 01:28:32 2012] [error] [client 46.248.160.248]     transaction.rollback_unless_managed(using=conn), referer: http://canvastest.leszniak.pl/wyszukaj
[Fri Nov 30 01:28:32 2012] [error] [client 46.248.160.248]   File "/usr/lib/python2.7/dist-packages/django/db/transaction.py", line 129, in rollback_unless_managed, referer: http://canvastest.leszniak.pl/wyszukaj
[Fri Nov 30 01:28:32 2012] [error] [client 46.248.160.248] unable to init Zlib: deflateInit2 returned -4: URL /wyszukaj, referer: http://canvastest.leszniak.pl/wyszukaj
[Fri Nov 30 09:20:58 2012] [error] [client 46.248.160.248] mod_wsgi (pid=5604): Exception occurred processing WSGI script '/home/projects/canvastest/canvastest/wsgi.py'., referer: http://canvastest.leszniak.pl/wyszukaj
[Fri Nov 30 09:20:58 2012] [error] [client 46.248.160.248] Traceback (most recent call last):, referer: http://canvastest.leszniak.pl/wyszukaj
[Fri Nov 30 09:20:58 2012] [error] [client 46.248.160.248]   File "/usr/lib/python2.7/dist-packages/django/core/handlers/wsgi.py", line 219, in __call__, referer: http://canvastest.leszniak.pl/wyszukaj
[Fri Nov 30 09:20:58 2012] [error] [client 46.248.160.248]     self.load_middleware(), referer: http://canvastest.leszniak.pl/wyszukaj
[Fri Nov 30 09:20:58 2012] [error] [client 46.248.160.248]   File "/usr/lib/python2.7/dist-packages/django/core/handlers/base.py", line 39, in load_middleware, referer: http://canvastest.leszniak.pl/wyszukaj
[Fri Nov 30 09:20:58 2012] [error] [client 46.248.160.248]     for middleware_path in settings.MIDDLEWARE_CLASSES:, referer: http://canvastest.leszniak.pl/wyszukaj
[Fri Nov 30 09:20:58 2012] [error] [client 46.248.160.248]   File "/usr/lib/python2.7/dist-packages/django/utils/functional.py", line 184, in inner, referer: http://canvastest.leszniak.pl/wyszukaj
[Fri Nov 30 09:20:58 2012] [error] [client 46.248.160.248]     self._setup(), referer: http://canvastest.leszniak.pl/wyszukaj
[Fri Nov 30 09:20:58 2012] [error] [client 46.248.160.248]   File "/usr/lib/python2.7/dist-packages/django/conf/__init__.py", line 42, in _setup, referer: http://canvastest.leszniak.pl/wyszukaj
[Fri Nov 30 09:20:58 2012] [error] [client 46.248.160.248]     self._wrapped = Settings(settings_module), referer: http://canvastest.leszniak.pl/wyszukaj
[Fri Nov 30 09:20:58 2012] [error] [client 46.248.160.248]   File "/usr/lib/python2.7/dist-packages/django/conf/__init__.py", line 118, in __init__, referer: http://canvastest.leszniak.pl/wyszukaj
[Fri Nov 30 09:20:58 2012] [error] [client 46.248.160.248]     raise ValueError("Incorrect timezone setting: %s" % self.TIME_ZONE), referer: http://canvastest.leszniak.pl/wyszukaj
[Fri Nov 30 09:20:58 2012] [error] [client 46.248.160.248] ValueError: Incorrect timezone setting: Europe/Warsaw Poland, referer: http://canvastest.leszniak.pl/wyszukaj
[Fri Nov 30 09:21:00 2012] [error] [client 46.248.160.248] mod_wsgi (pid=5605): Exception occurred processing WSGI script '/home/projects/canvastest/canvastest/wsgi.py'., referer: http://canvastest.leszniak.pl/wyszukaj
[Fri Nov 30 09:21:00 2012] [error] [client 46.248.160.248] Traceback (most recent call last):, referer: http://canvastest.leszniak.pl/wyszukaj
[Fri Nov 30 09:21:00 2012] [error] [client 46.248.160.248]   File "/usr/lib/python2.7/dist-packages/django/core/handlers/wsgi.py", line 219, in __call__, referer: http://canvastest.leszniak.pl/wyszukaj
[Fri Nov 30 09:21:00 2012] [error] [client 46.248.160.248]     self.load_middleware(), referer: http://canvastest.leszniak.pl/wyszukaj
[Fri Nov 30 09:21:00 2012] [error] [client 46.248.160.248]   File "/usr/lib/python2.7/dist-packages/django/core/handlers/base.py", line 39, in load_middleware, referer: http://canvastest.leszniak.pl/wyszukaj
[Fri Nov 30 09:21:00 2012] [error] [client 46.248.160.248]     for middleware_path in settings.MIDDLEWARE_CLASSES:, referer: http://canvastest.leszniak.pl/wyszukaj
[Fri Nov 30 09:21:00 2012] [error] [client 46.248.160.248]   File "/usr/lib/python2.7/dist-packages/django/utils/functional.py", line 184, in inner, referer: http://canvastest.leszniak.pl/wyszukaj
[Fri Nov 30 09:21:00 2012] [error] [client 46.248.160.248]     self._setup(), referer: http://canvastest.leszniak.pl/wyszukaj
[Fri Nov 30 09:21:00 2012] [error] [client 46.248.160.248]   File "/usr/lib/python2.7/dist-packages/django/conf/__init__.py", line 42, in _setup, referer: http://canvastest.leszniak.pl/wyszukaj
[Fri Nov 30 09:21:00 2012] [error] [client 46.248.160.248]     self._wrapped = Settings(settings_module), referer: http://canvastest.leszniak.pl/wyszukaj
[Fri Nov 30 09:21:00 2012] [error] [client 46.248.160.248]   File "/usr/lib/python2.7/dist-packages/django/conf/__init__.py", line 118, in __init__, referer: http://canvastest.leszniak.pl/wyszukaj
[Fri Nov 30 09:21:00 2012] [error] [client 46.248.160.248]     raise ValueError("Incorrect timezone setting: %s" % self.TIME_ZONE), referer: http://canvastest.leszniak.pl/wyszukaj
[Fri Nov 30 09:21:00 2012] [error] [client 46.248.160.248] ValueError: Incorrect timezone setting: Europe/Warsaw Poland, referer: http://canvastest.leszniak.pl/wyszukaj
[Fri Nov 30 09:21:04 2012] [error] [client 46.248.160.248] mod_wsgi (pid=5606): Exception occurred processing WSGI script '/home/projects/canvastest/canvastest/wsgi.py'., referer: http://canvastest.leszniak.pl/wyszukaj
[Fri Nov 30 09:21:04 2012] [error] [client 46.248.160.248] Traceback (most recent call last):, referer: http://canvastest.leszniak.pl/wyszukaj
[Fri Nov 30 09:21:04 2012] [error] [client 46.248.160.248]   File "/usr/lib/python2.7/dist-packages/django/core/handlers/wsgi.py", line 219, in __call__, referer: http://canvastest.leszniak.pl/wyszukaj
[Fri Nov 30 09:21:04 2012] [error] [client 46.248.160.248]     self.load_middleware(), referer: http://canvastest.leszniak.pl/wyszukaj
[Fri Nov 30 09:21:04 2012] [error] [client 46.248.160.248]   File "/usr/lib/python2.7/dist-packages/django/core/handlers/base.py", line 39, in load_middleware, referer: http://canvastest.leszniak.pl/wyszukaj
[Fri Nov 30 09:21:04 2012] [error] [client 46.248.160.248]     for middleware_path in settings.MIDDLEWARE_CLASSES:, referer: http://canvastest.leszniak.pl/wyszukaj
[Fri Nov 30 09:21:04 2012] [error] [client 46.248.160.248]   File "/usr/lib/python2.7/dist-packages/django/utils/functional.py", line 184, in inner, referer: http://canvastest.leszniak.pl/wyszukaj
[Fri Nov 30 09:21:04 2012] [error] [client 46.248.160.248]     self._setup(), referer: http://canvastest.leszniak.pl/wyszukaj
[Fri Nov 30 09:21:04 2012] [error] [client 46.248.160.248]   File "/usr/lib/python2.7/dist-packages/django/conf/__init__.py", line 42, in _setup, referer: http://canvastest.leszniak.pl/wyszukaj
[Fri Nov 30 09:21:04 2012] [error] [client 46.248.160.248]     self._wrapped = Settings(settings_module), referer: http://canvastest.leszniak.pl/wyszukaj
[Fri Nov 30 09:21:04 2012] [error] [client 46.248.160.248]   File "/usr/lib/python2.7/dist-packages/django/conf/__init__.py", line 118, in __init__, referer: http://canvastest.leszniak.pl/wyszukaj
[Fri Nov 30 09:21:04 2012] [error] [client 46.248.160.248]     raise ValueError("Incorrect timezone setting: %s" % self.TIME_ZONE), referer: http://canvastest.leszniak.pl/wyszukaj
[Fri Nov 30 09:21:04 2012] [error] [client 46.248.160.248] ValueError: Incorrect timezone setting: Europe/Warsaw Poland, referer: http://canvastest.leszniak.pl/wyszukaj
[Fri Nov 30 09:21:18 2012] [error] [client 46.248.160.248] mod_wsgi (pid=5613): Exception occurred processing WSGI script '/home/projects/canvastest/canvastest/wsgi.py'.
[Fri Nov 30 09:21:18 2012] [error] [client 46.248.160.248] Traceback (most recent call last):
[Fri Nov 30 09:21:18 2012] [error] [client 46.248.160.248]   File "/usr/lib/python2.7/dist-packages/django/core/handlers/wsgi.py", line 219, in __call__
[Fri Nov 30 09:21:18 2012] [error] [client 46.248.160.248]     self.load_middleware()
[Fri Nov 30 09:21:18 2012] [error] [client 46.248.160.248]   File "/usr/lib/python2.7/dist-packages/django/core/handlers/base.py", line 39, in load_middleware
[Fri Nov 30 09:21:18 2012] [error] [client 46.248.160.248]     for middleware_path in settings.MIDDLEWARE_CLASSES:
[Fri Nov 30 09:21:18 2012] [error] [client 46.248.160.248]   File "/usr/lib/python2.7/dist-packages/django/utils/functional.py", line 184, in inner
[Fri Nov 30 09:21:18 2012] [error] [client 46.248.160.248]     self._setup()
[Fri Nov 30 09:21:18 2012] [error] [client 46.248.160.248]   File "/usr/lib/python2.7/dist-packages/django/conf/__init__.py", line 42, in _setup
[Fri Nov 30 09:21:18 2012] [error] [client 46.248.160.248]     self._wrapped = Settings(settings_module)
[Fri Nov 30 09:21:18 2012] [error] [client 46.248.160.248]   File "/usr/lib/python2.7/dist-packages/django/conf/__init__.py", line 118, in __init__
[Fri Nov 30 09:21:18 2012] [error] [client 46.248.160.248]     raise ValueError("Incorrect timezone setting: %s" % self.TIME_ZONE)
[Fri Nov 30 09:21:18 2012] [error] [client 46.248.160.248] ValueError: Incorrect timezone setting: Europe/Warsaw Poland
[Fri Nov 30 09:21:20 2012] [error] [client 46.248.160.248] mod_wsgi (pid=5615): Exception occurred processing WSGI script '/home/projects/canvastest/canvastest/wsgi.py'.
[Fri Nov 30 09:21:20 2012] [error] [client 46.248.160.248] Traceback (most recent call last):
[Fri Nov 30 09:21:20 2012] [error] [client 46.248.160.248]   File "/usr/lib/python2.7/dist-packages/django/core/handlers/wsgi.py", line 219, in __call__
[Fri Nov 30 09:21:20 2012] [error] [client 46.248.160.248]     self.load_middleware()
[Fri Nov 30 09:21:20 2012] [error] [client 46.248.160.248]   File "/usr/lib/python2.7/dist-packages/django/core/handlers/base.py", line 39, in load_middleware
[Fri Nov 30 09:21:20 2012] [error] [client 46.248.160.248]     for middleware_path in settings.MIDDLEWARE_CLASSES:
[Fri Nov 30 09:21:20 2012] [error] [client 46.248.160.248]   File "/usr/lib/python2.7/dist-packages/django/utils/functional.py", line 184, in inner
[Fri Nov 30 09:21:20 2012] [error] [client 46.248.160.248]     self._setup()
[Fri Nov 30 09:21:20 2012] [error] [client 46.248.160.248]   File "/usr/lib/python2.7/dist-packages/django/conf/__init__.py", line 42, in _setup
[Fri Nov 30 09:21:20 2012] [error] [client 46.248.160.248]     self._wrapped = Settings(settings_module)
[Fri Nov 30 09:21:20 2012] [error] [client 46.248.160.248]   File "/usr/lib/python2.7/dist-packages/django/conf/__init__.py", line 118, in __init__
[Fri Nov 30 09:21:20 2012] [error] [client 46.248.160.248]     raise ValueError("Incorrect timezone setting: %s" % self.TIME_ZONE)
[Fri Nov 30 09:21:20 2012] [error] [client 46.248.160.248] ValueError: Incorrect timezone setting: Europe/Warsaw Poland
[Fri Nov 30 09:21:21 2012] [error] [client 46.248.160.248] mod_wsgi (pid=5616): Exception occurred processing WSGI script '/home/projects/canvastest/canvastest/wsgi.py'.
[Fri Nov 30 09:21:21 2012] [error] [client 46.248.160.248] Traceback (most recent call last):
[Fri Nov 30 09:21:21 2012] [error] [client 46.248.160.248]   File "/usr/lib/python2.7/dist-packages/django/core/handlers/wsgi.py", line 219, in __call__
[Fri Nov 30 09:21:21 2012] [error] [client 46.248.160.248]     self.load_middleware()
[Fri Nov 30 09:21:21 2012] [error] [client 46.248.160.248]   File "/usr/lib/python2.7/dist-packages/django/core/handlers/base.py", line 39, in load_middleware
[Fri Nov 30 09:21:21 2012] [error] [client 46.248.160.248]     for middleware_path in settings.MIDDLEWARE_CLASSES:
[Fri Nov 30 09:21:21 2012] [error] [client 46.248.160.248]   File "/usr/lib/python2.7/dist-packages/django/utils/functional.py", line 184, in inner
[Fri Nov 30 09:21:21 2012] [error] [client 46.248.160.248]     self._setup()
[Fri Nov 30 09:21:21 2012] [error] [client 46.248.160.248]   File "/usr/lib/python2.7/dist-packages/django/conf/__init__.py", line 42, in _setup
[Fri Nov 30 09:21:21 2012] [error] [client 46.248.160.248]     self._wrapped = Settings(settings_module)
[Fri Nov 30 09:21:21 2012] [error] [client 46.248.160.248]   File "/usr/lib/python2.7/dist-packages/django/conf/__init__.py", line 118, in __init__
[Fri Nov 30 09:21:21 2012] [error] [client 46.248.160.248]     raise ValueError("Incorrect timezone setting: %s" % self.TIME_ZONE)
[Fri Nov 30 09:21:21 2012] [error] [client 46.248.160.248] ValueError: Incorrect timezone setting: Europe/Warsaw Poland
[Fri Nov 30 09:21:22 2012] [error] [client 46.248.160.248] mod_wsgi (pid=5617): Exception occurred processing WSGI script '/home/projects/canvastest/canvastest/wsgi.py'.
[Fri Nov 30 09:21:22 2012] [error] [client 46.248.160.248] Traceback (most recent call last):
[Fri Nov 30 09:21:22 2012] [error] [client 46.248.160.248]   File "/usr/lib/python2.7/dist-packages/django/core/handlers/wsgi.py", line 219, in __call__
[Fri Nov 30 09:21:22 2012] [error] [client 46.248.160.248]     self.load_middleware()
[Fri Nov 30 09:21:22 2012] [error] [client 46.248.160.248]   File "/usr/lib/python2.7/dist-packages/django/core/handlers/base.py", line 39, in load_middleware
[Fri Nov 30 09:21:22 2012] [error] [client 46.248.160.248]     for middleware_path in settings.MIDDLEWARE_CLASSES:
[Fri Nov 30 09:21:22 2012] [error] [client 46.248.160.248]   File "/usr/lib/python2.7/dist-packages/django/utils/functional.py", line 184, in inner
[Fri Nov 30 09:21:22 2012] [error] [client 46.248.160.248]     self._setup()
[Fri Nov 30 09:21:22 2012] [error] [client 46.248.160.248]   File "/usr/lib/python2.7/dist-packages/django/conf/__init__.py", line 42, in _setup
[Fri Nov 30 09:21:22 2012] [error] [client 46.248.160.248]     self._wrapped = Settings(settings_module)
[Fri Nov 30 09:21:22 2012] [error] [client 46.248.160.248]   File "/usr/lib/python2.7/dist-packages/django/conf/__init__.py", line 118, in __init__
[Fri Nov 30 09:21:22 2012] [error] [client 46.248.160.248]     raise ValueError("Incorrect timezone setting: %s" % self.TIME_ZONE)
[Fri Nov 30 09:21:22 2012] [error] [client 46.248.160.248] ValueError: Incorrect timezone setting: Europe/Warsaw Poland
